Workbook

Sheet Total oversikt
C2: Eiendomsinvesteringer for Leily AS
D4: Hafrsfjordgata 49 | F4: Adresse 2 | H4: Adresse 3 | J4: Adresse 4 | L4: Adresse 5 | N4: Total sum
B6: Verdi | D6: 7500000 | N6: =D6+F6+J6+H6+L6 -> 7500000
B7: Lån | D7: 6000000 | N7: =D7+F7+J7+H7+L7 -> 6000000
B8: Rente | D8: 5.68
B9: Lånebelastning pr. enhet | D9: =D7/D6 -> 0.8
B10: EK | D10: =D6-D7 -> 1500000 | N10: =D10+F10+J10+H10+L10 -> 1500000
B11: Lånebelastning totalt | N11: =N7/N6 -> 0.8
B13: UTGIFTER: pr. år
B14: Renteutgifter | D14: =(D7*D8)/100 -> 340800 | N14: =SUM(D14:L14) -> 340800
B15: Felles utgifter | D15: 3008 | N15: =SUM(D15:L15) -> 3008
B16: Kommunale avgifter | D16: 17840 | N16: =SUM(D16:L16) -> 17840
B17: Forsikring | D17: 2180 | N17: =SUM(D17:L17) -> 2180
B18: Strøm | D18: 575 | N18: =SUM(D18:L18) -> 575
B19: Avdrag * | D19: 35544 | N19: =SUM(D19:L19) -> 35544
B21: Utgifter pr. enhet: | D21: =SUM(D14:D19) -> 399947 | N21: =SUM(N14:N19) -> 399947
B23: INNTEKTER: pr. år
B24: Leieinntekt | D24: 0 | N24: =SUM(D24:L24) -> 0
B25: Diverse inntekt | D25: 0 | N25: =SUM(D25:L25) -> 0
B27: Inntekter pr. enhet | D27: =SUM(D24:D25) -> 0 | N27: =SUM(N24:N25) -> 0
B29: RESULTAT: før skatt | D29: =D27-D21 -> -399947 | N29: =N27-N21 -> -399947
B30: Skatt 22% | N30: =(N27-(N15+N16))*0.22 -> -4586.56
B31: RESULTAT: etter skatt | D31: =D29-D30 -> -399947 | N31: =N29-N30 -> -395360.44
B32: Rentefradrag | D32: =D14*0.22 -> 74976 | N32: =N14*0.22 -> 74976
B33: Resultat e/ rentefradrag | D33: =D31+D32 -> -324971 | N33: =N31+N32 -> -320384.44
B34: Pr. Mnd. | D34: =D33/12 -> -27080.917 | N34: =N33/12 -> -26698.703
B38: * Avdragsfri til | D38: 44550 | H38: 44489 | J38: 44489
B39: Hvis du har avdragsfrie lån så fører du det inn under
B42: NB! Dette arket er ikke koblet til noen lånekalkulator, så det er en forenklet utregning av renter. Ment kun for oversikt, ikke for kalkyler.
B43: F.eks.som en oversikt til bruk overfor banken din når du skal søke lån eller diskutere nye investeringer. Da må du selvsagt slette denne teksten.
B44: Pass på at du ser over denne oversikten og oppdaterer denne for din egen situasjon. Slett selvsagt kolonne for adresse 3 og 4 hvis du bare har 2 eiendommer.

Sheet Kalkyle - 2021
B2: Privat kalkyle eiendomsinvestering
B4: Hafrsfjordgata 49 | D4: 4010 | E4: Stavanger
C6: Verditakst | D6: Lånesum | E6: Lånebelastning | F6: Avdragsfrie år
C7: 7500000 | D7: =C13 -> 5766442.5 | E7: =D7/C7 -> 0.768859 | F7: 0
B10: Avkastning ved boligkjøp | E10: Cashflow per mnd | H10: Nettoyield på eiendommen **
B11: Totalpris eiendom | C11: 7688590 | E11: Leieinntekt | F11: =C16 -> 60000 | H11: Leieinntekter | I11: =C16*12 -> 720000
B12: Rente | C12: 6.5 | E12: Felleskost | F12: =C17 -> 0 | H12: Driftskostnader | I12: =(C17*12)+(C18*12)+(C19*12)+(C20*12)+(C21*12) -> 101172
B13: Lån | C13: =C11*C15 -> 5766442.5 | E13: Kom. Avg | F13: =C18 -> 2231 | H13: Netto leieinntekt | I13: =I11-I12 -> 618828
B14: Egenkapital | C14: =C11-C13 -> 1922147.5 | E14: Vedlikehold (5%) | F14: =C20 -> 2000 | H14: Kjøpesum | I14: =C11 -> 7688590
B15: Lånebelastning kjøpesum | C15: 0.75 | E15: Diverse | F15: =C21 -> 3000 | H15: Netto yield | I15: =I13/C11 -> 0.080486539
B16: Leieinntekt per mnd | C16: 60000 | E16: Skatt * | F16: =C23 -> 11345.18
B17: Felleskostnader pr. mnd | C17: 0 | E17: Ledighet (3%) | F17: =C19 -> 1200
B18: Kommunale avgifter pr. mnd. | C18: 2231
B19: Ledighet (3%) | C19: 1200 | E19: Renter og avdrag | F19: =('Lån - Kalkyle 2021'!M4+'Lån - Kalkyle 2021'!N4)/12 -> 38985.433
B20: Vedlikehold (5%) | C20: 2000 | E20: Cashflow per mnd | F20: =F11-F12-F13-F14-F15-F16-F17-F19 -> 1238.3873
B21: Strøm, forsikring, diverse | C21: 3000
B22: Netto leie pr. mnd. (før skatt) | C22: =C16-C17-C18-C19-C20-C21 -> 51569
B23: Skatt (22%) | C23: =C22*0.22 -> 11345.18
B24: Netto leie etter skatt | C24: =C22-C23 -> 40223.82
B25: Rentekostnad | C25: ='Lån - Kalkyle 2021'!M4/12 -> 31051.292
B26: Fradrag renter (22%) | C26: =C25*22% -> 6831.2842
B27: Sum etter finanskost og skatt | C27: =C24-C25+C26 -> 16003.812
B28: Netto pr. år | C28: =C27*12 -> 192045.75
B29: Avkastning egenkapitalen | C29: =C28/C14 -> 0.099912076
B37: Dette arket kopierer du og har et eget for hver eiendom og hvert år.

Sheet Lån - Kalkyle 2021
B2: Lånebeløp og betingelser | F2: Termin | G2: Terminbeløp | H2: Renter | I2: Avdrag | J2: Restgjeld | K2: Ekstra innbetalt | L2: Periode | M2: Renter pr. År | N2: Avdrag pr. År
B3: Lån | C3: ='Kalkyle - 2021'!C13 -> 5766442.5 | F3: 0 | J3: =C14 -> 5766442.5
B4: Nominell rente per år (PA) | C4: ='Kalkyle - 2021'!C12 -> 6.5 | F4: =IF(F3<>"",IF(J3>1,F3+1,""),"") -> 1 | G4: =IF(F4<>"",IF(J3>$C$15,$C$15,J3+H4),"") -> 38985.433 | H4: =IF(F4<>"",J3*$C$4%/$C$7+$C$8,"") -> 31284.897 | I4: =IF(F4<>"",IF(F4>$C$6*$C$7,G4-H4,0),"") -> 7700.5358 | J4: =IF(F4<>"",J3-I4-K4,"") -> 5758742 | L4: År 1 | M4: =SUM(H4:H15) -> 372615.5 | N4: =SUM(I4:I15) -> 95209.689
B5: Nedbetalingstid, antall år | C5: 25 | F5: =IF(F4<>"",IF(J4>1,F4+1,""),"") -> 2 | G5: =IF(F5<>"",IF(J4>$C$15,$C$15,J4+H5),"") -> 38985.433 | H5: =IF(F5<>"",J4*$C$4%/$C$7+$C$8,"") -> 31243.186 | I5: =IF(F5<>"",IF(F5>$C$6*$C$7,G5-H5,0),"") -> 7742.2471 | J5: =IF(F5<>"",J4-I5-K5,"") -> 5750999.7 | L5: År 2 | M5: =SUM(H16:H27) -> 366239.13 | N5: =SUM(I16:I27) -> 101586.06
B6: Avdragsfrie år | C6: ='Kalkyle - 2021'!F7 -> 0 | F6: =IF(F5<>"",IF(J5>1,F5+1,""),"") -> 3 | G6: =IF(F6<>"",IF(J5>$C$15,$C$15,J5+H6),"") -> 38985.433 | H6: =IF(F6<>"",J5*$C$4%/$C$7+$C$8,"") -> 31201.248 | I6: =IF(F6<>"",IF(F6>$C$6*$C$7,G6-H6,0),"") -> 7784.1842 | J6: =IF(F6<>"",J5-I6-K6,"") -> 5743215.5 | L6: År 3 | M6: =SUM(H28:H39) -> 359435.73 | N6: =SUM(I28:I39) -> 108389.46
B7: Terminer per år | C7: 12 | F7: =IF(F6<>"",IF(J6>1,F6+1,""),"") -> 4 | G7: =IF(F7<>"",IF(J6>$C$15,$C$15,J6+H7),"") -> 38985.433 | H7: =IF(F7<>"",J6*$C$4%/$C$7+$C$8,"") -> 31159.084 | I7: =IF(F7<>"",IF(F7>$C$6*$C$7,G7-H7,0),"") -> 7826.3486 | J7: =IF(F7<>"",J6-I7-K7,"") -> 5735389.2 | L7: År 4 | M7: =SUM(H40:H51) -> 352176.69 | N7: =SUM(I40:I51) -> 115648.51
B8: Termingebyr | C8: 50 | F8: =IF(F7<>"",IF(J7>1,F7+1,""),"") -> 5 | G8: =IF(F8<>"",IF(J7>$C$15,$C$15,J7+H8),"") -> 38985.433 | H8: =IF(F8<>"",J7*$C$4%/$C$7+$C$8,"") -> 31116.691 | I8: =IF(F8<>"",IF(F8>$C$6*$C$7,G8-H8,0),"") -> 7868.7413 | J8: =IF(F8<>"",J7-I8-K8,"") -> 5727520.4 | L8: År 5 | M8: =SUM(H52:H63) -> 344431.49 | N8: =SUM(I52:I63) -> 123393.7
B9: Tinglysningsgebyr | F9: =IF(F8<>"",IF(J8>1,F8+1,""),"") -> 6 | G9: =IF(F9<>"",IF(J8>$C$15,$C$15,J8+H9),"") -> 38985.433 | H9: =IF(F9<>"",J8*$C$4%/$C$7+$C$8,"") -> 31074.069 | I9: =IF(F9<>"",IF(F9>$C$6*$C$7,G9-H9,0),"") -> 7911.3636 | J9: =IF(F9<>"",J8-I9-K9,"") -> 5719609.1 | L9: År 6 | M9: =SUM(H64:H75) -> 336167.59 | N9: =SUM(I64:I75) -> 131657.61
B10: Etableringsgebyr | C10: 950 | F10: =IF(F9<>"",IF(J9>1,F9+1,""),"") -> 7 | G10: =IF(F10<>"",IF(J9>$C$15,$C$15,J9+H10),"") -> 38985.433 | H10: =IF(F10<>"",J9*$C$4%/$C$7+$C$8,"") -> 31031.216 | I10: =IF(F10<>"",IF(F10>$C$6*$C$7,G10-H10,0),"") -> 7954.2169 | J10: =IF(F10<>"",J9-I10-K10,"") -> 5711654.9 | L10: År 7 | M10: =SUM(H76:H87) -> 327350.23 | N10: =SUM(I76:I87) -> 140474.96
B11: Inkludere gebyrer i lånebeløp? | C11: Ja | F11: =IF(F10<>"",IF(J10>1,F10+1,""),"") -> 8 | G11: =IF(F11<>"",IF(J10>$C$15,$C$15,J10+H11),"") -> 38985.433 | H11: =IF(F11<>"",J10*$C$4%/$C$7+$C$8,"") -> 30988.131 | I11: =IF(F11<>"",IF(F11>$C$6*$C$7,G11-H11,0),"") -> 7997.3022 | J11: =IF(F11<>"",J10-I11-K11,"") -> 5703657.6 | L11: År 8 | M11: =SUM(H88:H99) -> 317942.36 | N11: =SUM(I88:I99) -> 149882.83
F12: =IF(F11<>"",IF(J11>1,F11+1,""),"") -> 9 | G12: =IF(F12<>"",IF(J11>$C$15,$C$15,J11+H12),"") -> 38985.433 | H12: =IF(F12<>"",J11*$C$4%/$C$7+$C$8,"") -> 30944.812 | I12: =IF(F12<>"",IF(F12>$C$6*$C$7,G12-H12,0),"") -> 8040.6209 | J12: =IF(F12<>"",J11-I12-K12,"") -> 5695616.9 | L12: År 9 | M12: =SUM(H100:H111) -> 307904.43 | N12: =SUM(I100:I111) -> 159920.76
B13: Avdrag, renter andre kostnader | D13: Effekt ekstra innb | F13: =IF(F12<>"",IF(J12>1,F12+1,""),"") -> 10 | G13: =IF(F13<>"",IF(J12>$C$15,$C$15,J12+H13),"") -> 38985.433 | H13: =IF(F13<>"",J12*$C$4%/$C$7+$C$8,"") -> 30901.258 | I13: =IF(F13<>"",IF(F13>$C$6*$C$7,G13-H13,0),"") -> 8084.1743 | J13: =IF(F13<>"",J12-I13-K13,"") -> 5687532.8 | L13: År 10 | M13: =SUM(H112:H123) -> 297194.24 | N13: =SUM(I112:I123) -> 170630.95
B14: Lånebeløp inkl gebyrer | C14: =C3 -> 5766442.5 | F14: =IF(F13<>"",IF(J13>1,F13+1,""),"") -> 11 | G14: =IF(F14<>"",IF(J13>$C$15,$C$15,J13+H14),"") -> 38985.433 | H14: =IF(F14<>"",J13*$C$4%/$C$7+$C$8,"") -> 30857.469 | I14: =IF(F14<>"",IF(F14>$C$6*$C$7,G14-H14,0),"") -> 8127.9636 | J14: =IF(F14<>"",J13-I14-K14,"") -> 5679404.8
B15: Avdrag og rente/termin | C15: =IFERROR(PMT(C4%/C7,(C5-C6)*C7,C14)*-1+C8,"") -> 38985.433 | F15: =IF(F14<>"",IF(J14>1,F14+1,""),"") -> 12 | G15: =IF(F15<>"",IF(J14>$C$15,$C$15,J14+H15),"") -> 38985.433 | H15: =IF(F15<>"",J14*$C$4%/$C$7+$C$8,"") -> 30813.443 | I15: =IF(F15<>"",IF(F15>$C$6*$C$7,G15-H15,0),"") -> 8171.99 | J15: =IF(F15<>"",J14-I15-K15,"") -> 5671232.8
B16: Nedbetalt i perioden | C16: =IFERROR(C15*C7*(C5-C6)+(C15*C6*C7),"") -> 11695630 | D16: =IF(SUM(K:K)<>0, SUM(H:I)-C16,"") | F16: =IF(F15<>"",IF(J15>1,F15+1,""),"") -> 13 | G16: =IF(F16<>"",IF(J15>$C$15,$C$15,J15+H16),"") -> 38985.433 | H16: =IF(F16<>"",J15*$C$4%/$C$7+$C$8,"") -> 30769.178 | I16: =IF(F16<>"",IF(F16>$C$6*$C$7,G16-H16,0),"") -> 8216.255 | J16: =IF(F16<>"",J15-I16-K16,"") -> 5663016.6
B17: Renter | C17: =IFERROR(C16-C14,"") -> 5929187.3 | D17: =IF(SUM(K:K)<>0, SUM(H:H)-C17,"") | F17: =IF(F16<>"",IF(J16>1,F16+1,""),"") -> 14 | G17: =IF(F17<>"",IF(J16>$C$15,$C$15,J16+H17),"") -> 38985.433 | H17: =IF(F17<>"",J16*$C$4%/$C$7+$C$8,"") -> 30724.673 | I17: =IF(F17<>"",IF(F17>$C$6*$C$7,G17-H17,0),"") -> 8260.7597 | J17: =IF(F17<>"",J16-I17-K17,"") -> 5654755.8
B18: Etablering og tinglysning | C18: =C9+C10 -> 950 | F18: =IF(F17<>"",IF(J17>1,F17+1,""),"") -> 15 | G18: =IF(F18<>"",IF(J17>$C$15,$C$15,J17+H18),"") -> 38985.433 | H18: =IF(F18<>"",J17*$C$4%/$C$7+$C$8,"") -> 30679.927 | I18: =IF(F18<>"",IF(F18>$C$6*$C$7,G18-H18,0),"") -> 8305.5055 | J18: =IF(F18<>"",J17-I18-K18,"") -> 5646450.3
B19: Sum kostnader | C19: =SUM(C17:C18) -> 5930137.3 | D19: =IFERROR(D17+D18,"") | F19: =IF(F18<>"",IF(J18>1,F18+1,""),"") -> 16 | G19: =IF(F19<>"",IF(J18>$C$15,$C$15,J18+H19),"") -> 38985.433 | H19: =IF(F19<>"",J18*$C$4%/$C$7+$C$8,"") -> 30634.939 | I19: =IF(F19<>"",IF(F19>$C$6*$C$7,G19-H19,0),"") -> 8350.4936 | J19: =IF(F19<>"",J18-I19-K19,"") -> 5638099.8
B20: Total kostnad i % av lånesum | C20: =IFERROR($C$19/$C$3%,"") -> 102.83875 | D20: =IFERROR($D$19/$C$3%,"") | F20: =IF(F19<>"",IF(J19>1,F19+1,""),"") -> 17 | G20: =IF(F20<>"",IF(J19>$C$15,$C$15,J19+H20),"") -> 38985.433 | H20: =IF(F20<>"",J19*$C$4%/$C$7+$C$8,"") -> 30589.707 | I20: =IF(F20<>"",IF(F20>$C$6*$C$7,G20-H20,0),"") -> 8395.7255 | J20: =IF(F20<>"",J19-I20-K20,"") -> 5629704.1
B21: Termingebyr utgjør | C21: =C8*C7*C5 -> 15000 | F21: =IF(F20<>"",IF(J20>1,F20+1,""),"") -> 18 | G21: =IF(F21<>"",IF(J20>$C$15,$C$15,J20+H21),"") -> 38985.433 | H21: =IF(F21<>"",J20*$C$4%/$C$7+$C$8,"") -> 30544.23 | I21: =IF(F21<>"",IF(F21>$C$6*$C$7,G21-H21,0),"") -> 8441.2023 | J21: =IF(F21<>"",J20-I21-K21,"") -> 5621262.9
F22: =IF(F21<>"",IF(J21>1,F21+1,""),"") -> 19 | G22: =IF(F22<>"",IF(J21>$C$15,$C$15,J21+H22),"") -> 38985.433 | H22: =IF(F22<>"",J21*$C$4%/$C$7+$C$8,"") -> 30498.507 | I22: =IF(F22<>"",IF(F22>$C$6*$C$7,G22-H22,0),"") -> 8486.9255 | J22: =IF(F22<>"",J21-I22-K22,"") -> 5612775.9
B23: Kostnad ved forskjellig nedbetalingstid | D23: % | F23: =IF(F22<>"",IF(J22>1,F22+1,""),"") -> 20 | G23: =IF(F23<>"",IF(J22>$C$15,$C$15,J22+H23),"") -> 38985.433 | H23: =IF(F23<>"",J22*$C$4%/$C$7+$C$8,"") -> 30452.536 | I23: =IF(F23<>"",IF(F23>$C$6*$C$7,G23-H23,0),"") -> 8532.8964 | J23: =IF(F23<>"",J22-I23-K23,"") -> 5604243
A24: =3-$C$6 -> 3 | B24: =A24+$C$6&" år" -> 3 år | C24: =IFERROR((PMT($C$4%/$C$7,A24*$C$7,$C$14)*-1)*$C$7*A24-$C$14+($C$15*$C$6*$C$7)+$C$8*$C$5*$C$7+$C$18,"") -> 611993.16 | D24: =IFERROR(C24/$C$3%,"") -> 10.613011 | F24: =IF(F23<>"",IF(J23>1,F23+1,""),"") -> 21 | G24: =IF(F24<>"",IF(J23>$C$15,$C$15,J23+H24),"") -> 38985.433 | H24: =IF(F24<>"",J23*$C$4%/$C$7+$C$8,"") -> 30406.317 | I24: =IF(F24<>"",IF(F24>$C$6*$C$7,G24-H24,0),"") -> 8579.1162 | J24: =IF(F24<>"",J23-I24-K24,"") -> 5595663.9
A25: =4-$C$6 -> 4 | B25: =A25+$C$6&" år" -> 4 år | C25: =IFERROR((PMT($C$4%/$C$7,A25*$C$7,$C$14)*-1)*$C$7*A25-$C$14+($C$15*$C$6*$C$7)+$C$8*$C$5*$C$7+$C$18,"") -> 813551.3 | D25: =IFERROR(C25/$C$3%,"") -> 14.108374 | F25: =IF(F24<>"",IF(J24>1,F24+1,""),"") -> 22 | G25: =IF(F25<>"",IF(J24>$C$15,$C$15,J24+H25),"") -> 38985.433 | H25: =IF(F25<>"",J24*$C$4%/$C$7+$C$8,"") -> 30359.846 | I25: =IF(F25<>"",IF(F25>$C$6*$C$7,G25-H25,0),"") -> 8625.5864 | J25: =IF(F25<>"",J24-I25-K25,"") -> 5587038.3
A26: =5-$C$6 -> 5 | B26: =A26+$C$6&" år" -> 5 år | C26: =IFERROR((PMT($C$4%/$C$7,A26*$C$7,$C$14)*-1)*$C$7*A26-$C$14+($C$15*$C$6*$C$7)+$C$8*$C$5*$C$7+$C$18,"") -> 1019131.6 | D26: =IFERROR(C26/$C$3%,"") -> 17.67349 | F26: =IF(F25<>"",IF(J25>1,F25+1,""),"") -> 23 | G26: =IF(F26<>"",IF(J25>$C$15,$C$15,J25+H26),"") -> 38985.433 | H26: =IF(F26<>"",J25*$C$4%/$C$7+$C$8,"") -> 30313.124 | I26: =IF(F26<>"",IF(F26>$C$6*$C$7,G26-H26,0),"") -> 8672.3083 | J26: =IF(F26<>"",J25-I26-K26,"") -> 5578366
A27: =6-$C$6 -> 6 | B27: =A27+$C$6&" år" -> 6 år | C27: =IFERROR((PMT($C$4%/$C$7,A27*$C$7,$C$14)*-1)*$C$7*A27-$C$14+($C$15*$C$6*$C$7)+$C$8*$C$5*$C$7+$C$18,"") -> 1228719 | D27: =IFERROR(C27/$C$3%,"") -> 21.308094 | F27: =IF(F26<>"",IF(J26>1,F26+1,""),"") -> 24 | G27: =IF(F27<>"",IF(J26>$C$15,$C$15,J26+H27),"") -> 38985.433 | H27: =IF(F27<>"",J26*$C$4%/$C$7+$C$8,"") -> 30266.149 | I27: =IF(F27<>"",IF(F27>$C$6*$C$7,G27-H27,0),"") -> 8719.2833 | J27: =IF(F27<>"",J26-I27-K27,"") -> 5569646.8
A28: =7-$C$6 -> 7 | B28: =A28+$C$6&" år" -> 7 år | C28: =IFERROR((PMT($C$4%/$C$7,A28*$C$7,$C$14)*-1)*$C$7*A28-$C$14+($C$15*$C$6*$C$7)+$C$8*$C$5*$C$7+$C$18,"") -> 1442294.9 | D28: =IFERROR(C28/$C$3%,"") -> 25.011867 | F28: =IF(F27<>"",IF(J27>1,F27+1,""),"") -> 25 | G28: =IF(F28<>"",IF(J27>$C$15,$C$15,J27+H28),"") -> 38985.433 | H28: =IF(F28<>"",J27*$C$4%/$C$7+$C$8,"") -> 30218.92 | I28: =IF(F28<>"",IF(F28>$C$6*$C$7,G28-H28,0),"") -> 8766.5128 | J28: =IF(F28<>"",J27-I28-K28,"") -> 5560880.2
A29: =10-$C$6 -> 10 | B29: =A29+$C$6&" år" -> 10 år | C29: =IFERROR((PMT($C$4%/$C$7,A29*$C$7,$C$14)*-1)*$C$7*A29-$C$14+($C$15*$C$6*$C$7)+$C$8*$C$5*$C$7+$C$18,"") -> 2106722.1 | D29: =IFERROR(C29/$C$3%,"") -> 36.534173 | F29: =IF(F28<>"",IF(J28>1,F28+1,""),"") -> 26 | G29: =IF(F29<>"",IF(J28>$C$15,$C$15,J28+H29),"") -> 38985.433 | H29: =IF(F29<>"",J28*$C$4%/$C$7+$C$8,"") -> 30171.435 | I29: =IF(F29<>"",IF(F29>$C$6*$C$7,G29-H29,0),"") -> 8813.9981 | J29: =IF(F29<>"",J28-I29-K29,"") -> 5552066.2
A30: 15 | B30: =A30+$C$6&" år" -> 15 år | C30: =IFERROR((PMT($C$4%/$C$7,A30*$C$7,$C$14)*-1)*$C$7*A30-$C$14+($C$15*$C$6*$C$7)+$C$8*$C$5*$C$7+$C$18,"") -> 3291250.5 | D30: =IFERROR(C30/$C$3%,"") -> 57.075926 | F30: =IF(F29<>"",IF(J29>1,F29+1,""),"") -> 27 | G30: =IF(F30<>"",IF(J29>$C$15,$C$15,J29+H30),"") -> 38985.433 | H30: =IF(F30<>"",J29*$C$4%/$C$7+$C$8,"") -> 30123.692 | I30: =IF(F30<>"",IF(F30>$C$6*$C$7,G30-H30,0),"") -> 8861.7406 | J30: =IF(F30<>"",J29-I30-K30,"") -> 5543204.5
A31: =20-$C$6 -> 20 | B31: =A31+$C$6&" år" -> 20 år | C31: =IFERROR((PMT($C$4%/$C$7,A31*$C$7,$C$14)*-1)*$C$7*A31-$C$14+($C$15*$C$6*$C$7)+$C$8*$C$5*$C$7+$C$18,"") -> 4567838.6 | D31: =IFERROR(C31/$C$3%,"") -> 79.214153 | F31: =IF(F30<>"",IF(J30>1,F30+1,""),"") -> 28 | G31: =IF(F31<>"",IF(J30>$C$15,$C$15,J30+H31),"") -> 38985.433 | H31: =IF(F31<>"",J30*$C$4%/$C$7+$C$8,"") -> 30075.691 | I31: =IF(F31<>"",IF(F31>$C$6*$C$7,G31-H31,0),"") -> 8909.7417 | J31: =IF(F31<>"",J30-I31-K31,"") -> 5534294.8
A32: =25-$C$6 -> 25 | B32: =A32+$C$6&" år" -> 25 år | C32: =IFERROR((PMT($C$4%/$C$7,A32*$C$7,$C$14)*-1)*$C$7*A32-$C$14+($C$15*$C$6*$C$7)+$C$8*$C$5*$C$7+$C$18,"") -> 5930137.3 | D32: =IFERROR(C32/$C$3%,"") -> 102.83875 | F32: =IF(F31<>"",IF(J31>1,F31+1,""),"") -> 29 | G32: =IF(F32<>"",IF(J31>$C$15,$C$15,J31+H32),"") -> 38985.433 | H32: =IF(F32<>"",J31*$C$4%/$C$7+$C$8,"") -> 30027.43 | I32: =IF(F32<>"",IF(F32>$C$6*$C$7,G32-H32,0),"") -> 8958.0028 | J32: =IF(F32<>"",J31-I32-K32,"") -> 5525336.8
A33: =30-$C$6 -> 30 | B33: =A33+$C$6&" år" -> 30 år | C33: =IFERROR((PMT($C$4%/$C$7,A33*$C$7,$C$14)*-1)*$C$7*A33-$C$14+($C$15*$C$6*$C$7)+$C$8*$C$5*$C$7+$C$18,"") -> 7370729.6 | D33: =IFERROR(C33/$C$3%,"") -> 127.82109 | F33: =IF(F32<>"",IF(J32>1,F32+1,""),"") -> 30 | G33: =IF(F33<>"",IF(J32>$C$15,$C$15,J32+H33),"") -> 38985.433 | H33: =IF(F33<>"",J32*$C$4%/$C$7+$C$8,"") -> 29978.907 | I33: =IF(F33<>"",IF(F33>$C$6*$C$7,G33-H33,0),"") -> 9006.5253 | J33: =IF(F33<>"",J32-I33-K33,"") -> 5516330.2
A34: =35-$C$6 -> 35 | B34: =A34+$C$6&" år" -> 35 år | C34: =IFERROR((PMT($C$4%/$C$7,A34*$C$7,$C$14)*-1)*$C$7*A34-$C$14+($C$15*$C$6*$C$7)+$C$8*$C$5*$C$7+$C$18,"") -> 8881556.3 | D34: =IFERROR(C34/$C$3%,"") -> 154.02141 | F34: =IF(F33<>"",IF(J33>1,F33+1,""),"") -> 31 | G34: =IF(F34<>"",IF(J33>$C$15,$C$15,J33+H34),"") -> 38985.433 | H34: =IF(F34<>"",J33*$C$4%/$C$7+$C$8,"") -> 29930.122 | I34: =IF(F34<>"",IF(F34>$C$6*$C$7,G34-H34,0),"") -> 9055.3106 | J34: =IF(F34<>"",J33-I34-K34,"") -> 5507274.9
A35: =40-$C$6 -> 40 | B35: =A35+$C$6&" år" -> 40 år | C35: =IFERROR((PMT($C$4%/$C$7,A35*$C$7,$C$14)*-1)*$C$7*A35-$C$14+($C$15*$C$6*$C$7)+$C$8*$C$5*$C$7+$C$18,"") -> 10454322 | D35: =IFERROR(C35/$C$3%,"") -> 181.29587 | F35: =IF(F34<>"",IF(J34>1,F34+1,""),"") -> 32 | G35: =IF(F35<>"",IF(J34>$C$15,$C$15,J34+H35),"") -> 38985.433 | H35: =IF(F35<>"",J34*$C$4%/$C$7+$C$8,"") -> 29881.072 | I35: =IF(F35<>"",IF(F35>$C$6*$C$7,G35-H35,0),"") -> 9104.3602 | J35: =IF(F35<>"",J34-I35-K35,"") -> 5498170.6
F36: =IF(F35<>"",IF(J35>1,F35+1,""),"") -> 33 | G36: =IF(F36<>"",IF(J35>$C$15,$C$15,J35+H36),"") -> 38985.433 | H36: =IF(F36<>"",J35*$C$4%/$C$7+$C$8,"") -> 29831.757 | I36: =IF(F36<>"",IF(F36>$C$6*$C$7,G36-H36,0),"") -> 9153.6755 | J36: =IF(F36<>"",J35-I36-K36,"") -> 5489016.9
B37: Effekt av ekstra innbetaling | F37: =IF(F36<>"",IF(J36>1,F36+1,""),"") -> 34 | G37: =IF(F37<>"",IF(J36>$C$15,$C$15,J36+H37),"") -> 38985.433 | H37: =IF(F37<>"",J36*$C$4%/$C$7+$C$8,"") -> 29782.175 | I37: =IF(F37<>"",IF(F37>$C$6*$C$7,G37-H37,0),"") -> 9203.2579 | J37: =IF(F37<>"",J36-I37-K37,"") -> 5479813.6
B38: Sum renter | C38: =SUM(H:H) -> 5929187.3 | F38: =IF(F37<>"",IF(J37>1,F37+1,""),"") -> 35 | G38: =IF(F38<>"",IF(J37>$C$15,$C$15,J37+H38),"") -> 38985.433 | H38: =IF(F38<>"",J37*$C$4%/$C$7+$C$8,"") -> 29732.324 | I38: =IF(F38<>"",IF(F38>$C$6*$C$7,G38-H38,0),"") -> 9253.1089 | J38: =IF(F38<>"",J37-I38-K38,"") -> 5470560.5
B39: Ekstra innbetalt | C39: =SUM(K:K) -> 0 | F39: =IF(F38<>"",IF(J38>1,F38+1,""),"") -> 36 | G39: =IF(F39<>"",IF(J38>$C$15,$C$15,J38+H39),"") -> 38985.433 | H39: =IF(F39<>"",J38*$C$4%/$C$7+$C$8,"") -> 29682.203 | I39: =IF(F39<>"",IF(F39>$C$6*$C$7,G39-H39,0),"") -> 9303.2299 | J39: =IF(F39<>"",J38-I39-K39,"") -> 5461257.3
B40: Spart rentekostnad | C40: =C17-C38 -> 7.4505806e-09 | F40: =IF(F39<>"",IF(J39>1,F39+1,""),"") -> 37 | G40: =IF(F40<>"",IF(J39>$C$15,$C$15,J39+H40),"") -> 38985.433 | H40: =IF(F40<>"",J39*$C$4%/$C$7+$C$8,"") -> 29631.81 | I40: =IF(F40<>"",IF(F40>$C$6*$C$7,G40-H40,0),"") -> 9353.6224 | J40: =IF(F40<>"",J39-I40-K40,"") -> 5451903.7
F41: =IF(F40<>"",IF(J40>1,F40+1,""),"") -> 38 | G41: =IF(F41<>"",IF(J40>$C$15,$C$15,J40+H41),"") -> 38985.433 | H41: =IF(F41<>"",J40*$C$4%/$C$7+$C$8,"") -> 29581.145 | I41: =IF(F41<>"",IF(F41>$C$6*$C$7,G41-H41,0),"") -> 9404.2879 | J41: =IF(F41<>"",J40-I41-K41,"") -> 5442499.4
...

Sheet Risiko
A1: RISIKOVURDERING OG PACE-PLAN
A3: RISIKO- OG SÅRBARHETSANALYSE (ROS)
A4: Hendelse / risiko | B4: Sannsynlighet (1–5) | C4: Konsekvens (1–5) | D4: Risikonivå | E4: Kommentar / beskrivelse | F4: Tiltak / reduksjon
A5: Ledighet / tap av leietakere | B5: 3 | C5: 3 | D5: =B5*C5 -> 9 | E5: Kan føre til lavere kontantstrøm i perioder | F5: Opprette bufferkonto, aktiv markedsføring
A6: Renteøkning | B6: 2 | C6: 4 | D6: =B6*C6 -> 8 | E6: Rente stiger over 6 %, høyere månedlige kostnader | F6: Vurdere fastrente eller ekstra nedbetaling
A7: Uforutsett vedlikehold | B7: 4 | C7: 3 | D7: =B7*C7 -> 12 | E7: Tak, rør eller bad krever akutt utbedring | F7: Opprette vedlikeholdsfond
A8: Endring i boligmarkedet | B8: 2 | C8: 4 | D8: =B8*C8 -> 8 | E8: Lavere verdi ved salg | F8: Langsiktig investeringshorisont
A9: Forsikringskostnader øker | B9: 3 | C9: 2 | D9: =B9*C9 -> 6 | E9: Prisjusteringer fra forsikringsselskap | F9: Sammenligne forsikring årlig
A12: PACE-PLAN (Primary, Alternate, Contingency, Emergency)
A13: Risiko / situasjon | B13: Primary (hovedløsning) | C13: Alternate (alternativ) | D13: Contingency (reserve) | E13: Emergency (kriseplan) | F13: Ansvarlig
A14: Ledighet | B14: Screening av leietakere | C14: Prisjustering | D14: Markedsføring | E14: Korttidsutleie (Airbnb) | F14: Utleieansvarlig
A15: Renteøkning | B15: Forhandle lavere rente | C15: Fast rente | D15: Ekstra nedbetaling | E15: Selge eiendom | F15: Daglig leder
A16: Vedlikehold | B16: Forebyggende vedlikehold | C16: Serviceavtaler | D16: Vedlikeholdsfond | E16: Leie inn entreprenør | F16: Driftsansvarlig
A17: Tap av leieinntekt | B17: Forsikring for leietap | C17: Bufferkonto | D17: Lån fra eier | E17: Salg av inventar | F17: Økonomiansvarlig
A19: OPPSUMMERING OG TOTAL RISIKOVURDERING
A21: Gjennomsnittlig risikonivå | B21: =AVERAGE(D5:D9) -> 8.6
A22: Kommentar til risikobilde | B22: Samlet risiko vurderes som middels. Tiltak bør revideres årlig eller ved store markedsendringer.

Sheet Oversikt 1 objekt 2021
B2: Oversikt eiendomsinvestering og regnskap for årlig utleie
B4: Adresse | D4: Postnr | E4: Sted | F4: 2021
B5: Gnr. Xxx | C5: Bnr. XXX | D5: Snr. X | E5: x. etg. | F5: x kvm.
B6: Sameiet XX | E6: Bolig
B7: Leietaker: | C7: Fra: | D7: Til: | F7: Verditakst | G7: Lånesum | H7: Lånebelastning
B8: Navn navnesen | C8: 43831 | D8: 44196 | F8: 3150000 | G8: 2200000 | H8: =G8/F8 -> 0.6984127
B9: Navn navnesen
C12: Måned | D12: Leieinntekter | E12: Fellesutgifter | F12: Kom. Avg. | G12: Diverse | H12: Merknad
C13: Januar | D13: 14000 | E13: 2000 | F13: 1900
C14: Februar | D14: 14000 | E14: 2000 | G14: 2000 | H14: Ny ovn
C15: Mars | D15: 14000 | E15: 2000
C16: April | D16: 14000 | E16: 2000 | F16: 1900
C17: Mai | D17: 14000 | E17: 2000
C18: Juni | D18: 14000 | E18: 2000 | G18: 1000 | H18: Finn
C19: Juli | D19: 14000 | E19: 2000 | F19: 1900
C20: August | D20: 14000 | E20: 2000
C21: September | D21: 14000 | E21: 2000
C22: Oktober | D22: 14000 | E22: 2000 | F22: 1900
C23: November | D23: 14000 | E23: 2000
C24: Desember | D24: 14000 | E24: 2000 | G24: 2000 | H24: Kjøring
C25: Sum | D25: =SUM(D13:D24) -> 168000 | E25: =SUM(E13:E24) -> 24000 | F25: =SUM(F13:F24) -> 7600 | G25: =SUM(G13:G24) -> 5000
C27: Skattepliktig inntekt | D27: =D25-E25-F25-G25 -> 131400 | E27: Dette er det beløpet du skatter av umøblert *
C29: Skatt - 22% | D29: =D27*0.22 -> 28908
C31: Celler merket med denne fargen må fylles ut manuelt
B36: Dette arket kopierer du og har et eget ark for hver eiendom og hvert år.

Sheet Sammenligning A og B
B2: Sammenligning 2 eiendomsinvesteringer for utleie privat
B4: Eiendom A | F4: Eiendom B
B8: Verditakst | C8: Lånesum | D8: Lånebelastning | E8: Avdragsfrie år | F8: Verditakst | G8: Lånesum | H8: Lånebelastning
B9: 2750000 | C9: =C14 -> 1530000 | D9: =C9/B9 -> 0.55636364 | E9: 0 | F9: 3600000 | G9: =G14 -> 2040000 | H9: =G9/F9 -> 0.56666667
B11: Avkastning ved boligkjøp | F11: Avkastning ved boligkjøp
B12: Totalpris eiendom | C12: 2550000 | F12: Totalpris eiendom | G12: 3400000
B13: Rente | C13: 2.5 | F13: Rente | G13: =C13 -> 2.5
B14: Lån | C14: =C12*C16 -> 1530000 | F14: Lån | G14: =G12*G16 -> 2040000
B15: Egenkapital | C15: =C12-C14 -> 1020000 | F15: Egenkapital | G15: =G12-G14 -> 1360000
B16: Lånebelastning kjøpesum | C16: 0.6 | F16: Lånebelastning kjøpesum | G16: 0.6
B17: Leieinntekt per mnd | C17: 12000 | F17: Leieinntekt per mnd | G17: 19000
B18: Felleskostnader pr. mnd | C18: 1650 | F18: Felleskostnader pr. mnd | G18: 2000
B19: Kommunale avgifter pr. mnd. | C19: 700 | F19: Kommunale avgifter pr. mnd. | G19: 800
B20: Ledighet (3%) | C20: =C17*0.03 -> 360 | F20: Ledighet (3%) | G20: =G17*0.03 -> 570
B21: Vedlikehold (5%) | C21: =C17*0.05 -> 600 | F21: Vedlikehold (5%) | G21: =G17*0.05 -> 950
B22: Strøm, forsikring, diverse | C22: 0 | F22: Strøm, forsikring, diverse | G22: 0
B23: Netto leie pr. mnd. før skatt | C23: =C17-C18-C19-C20-C21-C22 -> 8690 | F23: Netto leie pr. mnd. før skatt | G23: =G17-G18-G19-G20-G21-G22 -> 14680
B24: Skatt (22%) | C24: =C23*0.22 -> 1911.8 | F24: Skatt (22%) | G24: =G23*0.22 -> 3229.6
B25: Netto leie etter skatt | C25: =C23-C24 -> 6778.2 | F25: Netto leie etter skatt | G25: =G23-G24 -> 11450.4
B26: Rentekostnad | C26: ='Lån A'!M4/12 -> 3206.484 | F26: Rentekostnad | G26: ='Lån B'!M4/12 -> 4257.9925
B27: Fradrag renter (22%) | C27: =C26*22% -> 705.42649 | F27: Fradrag renter (22%) | G27: =G26*22% -> 936.75834
B28: Sum etter finanskost og skatt | C28: =C25-C26+C27 -> 4277.1425 | F28: Sum etter finanskost og skatt | G28: =G25-G26+G27 -> 8129.1659
B29: Netto pr. år | C29: =C28*12 -> 51325.71 | F29: Netto pr. år | G29: =G28*12 -> 97549.991
B30: Avkastning egenkapitalen | C30: =C29/C15 -> 0.050319323 | F30: Avkastning egenkapitalen | G30: =G29/G15 -> 0.071727934
B32: Cashflow per mnd | C32: År 1 | F32: Cashflow per mnd | G32: År 1
B33: Leieinntekt | C33: =C17 -> 12000 | F33: Leieinntekt | G33: =G17 -> 19000
B34: Felleskost | C34: =C18 -> 1650 | F34: Felleskost | G34: =G18 -> 2000
B35: Kom. Avg | C35: =C19 -> 700 | F35: Kom. Avg | G35: =G19 -> 800
B36: Vedlikehold (5%) | C36: =C21 -> 600 | F36: Vedlikehold (5%) | G36: =G21 -> 950
B37: Diverse | C37: =C22 -> 0 | F37: Diverse | G37: =G22 -> 0
B38: Skatt | C38: =C24 -> 1911.8 | F38: Skatt | G38: =G24 -> 3229.6
B39: Ledighet (3%) | C39: =C20 -> 360 | F39: Ledighet (3%) | G39: =G20 -> 570
B40: Rentekostnad * | C40: ='Lån A'!M4/12 -> 3206.484 | F40: Rentekostnad * | G40: ='Lån B'!M4/12 -> 4257.9925
B41: Avdragsdel (egen sparing) | C41: ='Lån A'!N4/12 -> 2892.6194 | F41: Avdragsdel (egen sparing) | G41: ='Lån B'!N4/12 -> 3856.2275
B42: Cashflow per mnd | C42: =C33-C34-C35-C36-C37-C38-C39-C40-C41 -> 679.0966 | F42: Cashflow per mnd | G42: =G33-G34-G35-G36-G37-G38-G39-G40-G41 -> 3336.18
B44: Nettoyield på eiendommene - for å sammenligne med andre investeringer
B46: Leieinntekter | C46: =C17*12 -> 144000 | F46: Leieinntekter | G46: =G17*12 -> 228000
B47: Driftskostnader | C47: =(C18*12)+(C19*12)+(C20*12)+(C21*12)+(C22*12) -> 39720 | F47: Driftskostnader | G47: =(G18*12)+(G19*12)+(G20*12)+(G21*12)+(G22*12) -> 51840
B48: Netto leieinntekt | C48: =C46-C47 -> 104280 | F48: Netto leieinntekt | G48: =G46-G47 -> 176160
B50: Netto yield | C50: =C48/C12 -> 0.040894118 | F50: Netto yield | G50: =G48/G12 -> 0.051811765
...

Sheet Skatt ved salg
B2: Beregning av skatt på gevinst ved salg av sekundærbolig
D5: Kjøpesum | E5: 2000000
D6: Totale omkostninger ved kjøp | E6: =SUM(E9:E15) -> 58842
D8: Omkostninger spesifisert:
D9: Dokumentavgift | E9: =E5*0.025 -> 50000
D10: Eierskiftegebyr (hvis aktuelt) | E10: 7500
D11: Boligkjøperforsikring (hvis aktuelt)
D12: Evt. andre relaterte kjøpskostnader
D13: Tinglysingegebyr pantedokument | E13: 585
D14: Tinglysingegebyr skjøte | E14: 585
D15: Panteattest | E15: 172
C17: Inngangsverdi | E17: =E5+E6 -> 2058842
D19: Salgssum | E19: 2500000
D20: Totale omkostninger ved salg | E20: =SUM(E23:E28) -> 180000
D22: Omkostninger spesifisert:
D23: Meglerkostnader inkl. MF | E23: 75000
D24: Eierskifteforsikring (hvis aktuelt) | E24: 10000
D25: Styling (hvis aktuelt) | E25: 15000
D26: Takstmann | E26: 5000
D27: Diverse (hvis aktuelt)
D28: Oppgradering av boligens standard * | E28: 75000
C30: Utgangsverdi | E30: =E19-E20 -> 2320000
C32: Skattepliktig gevinst
D33: Utgangsverdi - salgsvederlag | E33: =E30 -> 2320000
C34: - | D34: Inngangsverdi | E34: =E17 -> 2058842
C35: = | D35: Skattepliktig gevinst | E35: =E33-E34 -> 261158
D37: Skatt - 22% | E37: =E35*0.22 -> 57454.76
C42: * Du kan ikke kreve fradrag for vedlikeholdskostnader, men det som regnes som
C43: oppgradering pga. nivåheving kan trekkes ifra på skattemessig beregning av
C44: gevinst ved salg. Disse kostnadene må kunne dokumenteres spesifisert.

Sheet Lån A
B2: Lånebeløp og betingelser | F2: Termin | G2: Terminbeløp | H2: Renter | I2: Avdrag | J2: Restgjeld | K2: Ekstra innbetalt | L2: Periode | M2: Renter pr. År | N2: Avdrag pr. År
B3: Lån | C3: ='Sammenligning A og B'!C14 -> 1530000 | F3: 0 | J3: =C14 -> 1530950
B4: Nominell rente per år (PA) | C4: ='Sammenligning A og B'!C13 -> 2.5 | F4: =IF(F3<>"",IF(J3>1,F3+1,""),"") -> 1 | G4: =IF(F4<>"",IF(J3>$C$15,$C$15,J3+H4),"") -> 6099.1034 | H4: =IF(F4<>"",J3*$C$4%/$C$7+$C$8,"") -> 3239.4792 | I4: =IF(F4<>"",IF(F4>$C$6*$C$7,G4-H4,0),"") -> 2859.6242 | J4: =IF(F4<>"",J3-I4-K4,"") -> 1528090.4 | L4: År 1 | M4: =SUM(H4:H15) -> 38477.808 | N4: =SUM(I4:I15) -> 34711.433
B5: Nedbetalingstid, antall år | C5: 30 | F5: =IF(F4<>"",IF(J4>1,F4+1,""),"") -> 2 | G5: =IF(F5<>"",IF(J4>$C$15,$C$15,J4+H5),"") -> 6099.1034 | H5: =IF(F5<>"",J4*$C$4%/$C$7+$C$8,"") -> 3233.5216 | I5: =IF(F5<>"",IF(F5>$C$6*$C$7,G5-H5,0),"") -> 2865.5818 | J5: =IF(F5<>"",J4-I5-K5,"") -> 1525224.8 | L5: År 2 | M5: =SUM(H16:H27) -> 37600.01 | N5: =SUM(I16:I27) -> 35589.231
B6: Avdragsfrie år | C6: ='Sammenligning A og B'!E9 -> 0 | F6: =IF(F5<>"",IF(J5>1,F5+1,""),"") -> 3 | G6: =IF(F6<>"",IF(J5>$C$15,$C$15,J5+H6),"") -> 6099.1034 | H6: =IF(F6<>"",J5*$C$4%/$C$7+$C$8,"") -> 3227.5517 | I6: =IF(F6<>"",IF(F6>$C$6*$C$7,G6-H6,0),"") -> 2871.5517 | J6: =IF(F6<>"",J5-I6-K6,"") -> 1522353.2 | L6: År 3 | M6: =SUM(H28:H39) -> 36700.013 | N6: =SUM(I28:I39) -> 36489.228
B7: Terminer per år | C7: 12 | F7: =IF(F6<>"",IF(J6>1,F6+1,""),"") -> 4 | G7: =IF(F7<>"",IF(J6>$C$15,$C$15,J6+H7),"") -> 6099.1034 | H7: =IF(F7<>"",J6*$C$4%/$C$7+$C$8,"") -> 3221.5693 | I7: =IF(F7<>"",IF(F7>$C$6*$C$7,G7-H7,0),"") -> 2877.5341 | J7: =IF(F7<>"",J6-I7-K7,"") -> 1519475.7 | L7: År 4 | M7: =SUM(H40:H51) -> 35777.257 | N7: =SUM(I40:I51) -> 37411.984
B8: Termingebyr | C8: 50 | F8: =IF(F7<>"",IF(J7>1,F7+1,""),"") -> 5 | G8: =IF(F8<>"",IF(J7>$C$15,$C$15,J7+H8),"") -> 6099.1034 | H8: =IF(F8<>"",J7*$C$4%/$C$7+$C$8,"") -> 3215.5744 | I8: =IF(F8<>"",IF(F8>$C$6*$C$7,G8-H8,0),"") -> 2883.529 | J8: =IF(F8<>"",J7-I8-K8,"") -> 1516592.2 | L8: År 5 | M8: =SUM(H52:H63) -> 34831.165 | N8: =SUM(I52:I63) -> 38358.075
B9: Tinglysningsgebyr | F9: =IF(F8<>"",IF(J8>1,F8+1,""),"") -> 6 | G9: =IF(F9<>"",IF(J8>$C$15,$C$15,J8+H9),"") -> 6099.1034 | H9: =IF(F9<>"",J8*$C$4%/$C$7+$C$8,"") -> 3209.567 | I9: =IF(F9<>"",IF(F9>$C$6*$C$7,G9-H9,0),"") -> 2889.5364 | J9: =IF(F9<>"",J8-I9-K9,"") -> 1513702.6 | L9: År 6 | M9: =SUM(H64:H75) -> 33861.149 | N9: =SUM(I64:I75) -> 39328.092
B10: Etableringsgebyr | C10: 950 | F10: =IF(F9<>"",IF(J9>1,F9+1,""),"") -> 7 | G10: =IF(F10<>"",IF(J9>$C$15,$C$15,J9+H10),"") -> 6099.1034 | H10: =IF(F10<>"",J9*$C$4%/$C$7+$C$8,"") -> 3203.5472 | I10: =IF(F10<>"",IF(F10>$C$6*$C$7,G10-H10,0),"") -> 2895.5562 | J10: =IF(F10<>"",J9-I10-K10,"") -> 1510807.1 | L10: År 7 | M10: =SUM(H76:H87) -> 32866.602 | N10: =SUM(I76:I87) -> 40322.639
B11: Inkludere gebyrer i lånebeløp? | C11: Ja | F11: =IF(F10<>"",IF(J10>1,F10+1,""),"") -> 8 | G11: =IF(F11<>"",IF(J10>$C$15,$C$15,J10+H11),"") -> 6099.1034 | H11: =IF(F11<>"",J10*$C$4%/$C$7+$C$8,"") -> 3197.5148 | I11: =IF(F11<>"",IF(F11>$C$6*$C$7,G11-H11,0),"") -> 2901.5886 | J11: =IF(F11<>"",J10-I11-K11,"") -> 1507905.5 | L11: År 8 | M11: =SUM(H88:H99) -> 31846.905 | N11: =SUM(I88:I99) -> 41342.336
F12: =IF(F11<>"",IF(J11>1,F11+1,""),"") -> 9 | G12: =IF(F12<>"",IF(J11>$C$15,$C$15,J11+H12),"") -> 6099.1034 | H12: =IF(F12<>"",J11*$C$4%/$C$7+$C$8,"") -> 3191.4698 | I12: =IF(F12<>"",IF(F12>$C$6*$C$7,G12-H12,0),"") -> 2907.6336 | J12: =IF(F12<>"",J11-I12-K12,"") -> 1504997.9 | L12: År 9 | M12: =SUM(H100:H111) -> 30801.421 | N12: =SUM(I100:I111) -> 42387.82
B13: Avdrag, renter andre kostnader | D13: Effekt ekstra innb | F13: =IF(F12<>"",IF(J12>1,F12+1,""),"") -> 10 | G13: =IF(F13<>"",IF(J12>$C$15,$C$15,J12+H13),"") -> 6099.1034 | H13: =IF(F13<>"",J12*$C$4%/$C$7+$C$8,"") -> 3185.4122 | I13: =IF(F13<>"",IF(F13>$C$6*$C$7,G13-H13,0),"") -> 2913.6912 | J13: =IF(F13<>"",J12-I13-K13,"") -> 1502084.2 | L13: År 10 | M13: =SUM(H112:H123) -> 29729.498 | N13: =SUM(I112:I123) -> 43459.743
B14: Lånebeløp inkl gebyrer | C14: =C3+IF(C11="Ja",C9+C10,0) -> 1530950 | F14: =IF(F13<>"",IF(J13>1,F13+1,""),"") -> 11 | G14: =IF(F14<>"",IF(J13>$C$15,$C$15,J13+H14),"") -> 6099.1034 | H14: =IF(F14<>"",J13*$C$4%/$C$7+$C$8,"") -> 3179.342 | I14: =IF(F14<>"",IF(F14>$C$6*$C$7,G14-H14,0),"") -> 2919.7614 | J14: =IF(F14<>"",J13-I14-K14,"") -> 1499164.4
B15: Avdrag og rente/termin | C15: =IFERROR(PMT(C4%/C7,(C5-C6)*C7,C14)*-1+C8,"") -> 6099.1034 | F15: =IF(F14<>"",IF(J14>1,F14+1,""),"") -> 12 | G15: =IF(F15<>"",IF(J14>$C$15,$C$15,J14+H15),"") -> 6099.1034 | H15: =IF(F15<>"",J14*$C$4%/$C$7+$C$8,"") -> 3173.2592 | I15: =IF(F15<>"",IF(F15>$C$6*$C$7,G15-H15,0),"") -> 2925.8442 | J15: =IF(F15<>"",J14-I15-K15,"") -> 1496238.6
B16: Nedbetalt i perioden | C16: =IFERROR(C15*C7*(C5-C6)+(C15*C6*C7),"") -> 2195677.2 | D16: =IF(SUM(K:K)<>0, SUM(H:I)-C16,"") | F16: =IF(F15<>"",IF(J15>1,F15+1,""),"") -> 13 | G16: =IF(F16<>"",IF(J15>$C$15,$C$15,J15+H16),"") -> 6099.1034 | H16: =IF(F16<>"",J15*$C$4%/$C$7+$C$8,"") -> 3167.1637 | I16: =IF(F16<>"",IF(F16>$C$6*$C$7,G16-H16,0),"") -> 2931.9397 | J16: =IF(F16<>"",J15-I16-K16,"") -> 1493306.6
B17: Renter | C17: =IFERROR(C16-C14,"") -> 664727.22 | D17: =IF(SUM(K:K)<>0, SUM(H:H)-C17,"") | F17: =IF(F16<>"",IF(J16>1,F16+1,""),"") -> 14 | G17: =IF(F17<>"",IF(J16>$C$15,$C$15,J16+H17),"") -> 6099.1034 | H17: =IF(F17<>"",J16*$C$4%/$C$7+$C$8,"") -> 3161.0555 | I17: =IF(F17<>"",IF(F17>$C$6*$C$7,G17-H17,0),"") -> 2938.0479 | J17: =IF(F17<>"",J16-I17-K17,"") -> 1490368.6
B18: Etablering og tinglysning | C18: =C9+C10 -> 950 | F18: =IF(F17<>"",IF(J17>1,F17+1,""),"") -> 15 | G18: =IF(F18<>"",IF(J17>$C$15,$C$15,J17+H18),"") -> 6099.1034 | H18: =IF(F18<>"",J17*$C$4%/$C$7+$C$8,"") -> 3154.9345 | I18: =IF(F18<>"",IF(F18>$C$6*$C$7,G18-H18,0),"") -> 2944.1689 | J18: =IF(F18<>"",J17-I18-K18,"") -> 1487424.4
B19: Sum kostnader | C19: =SUM(C17:C18) -> 665677.22 | D19: =IFERROR(D17+D18,"") | F19: =IF(F18<>"",IF(J18>1,F18+1,""),"") -> 16 | G19: =IF(F19<>"",IF(J18>$C$15,$C$15,J18+H19),"") -> 6099.1034 | H19: =IF(F19<>"",J18*$C$4%/$C$7+$C$8,"") -> 3148.8009 | I19: =IF(F19<>"",IF(F19>$C$6*$C$7,G19-H19,0),"") -> 2950.3025 | J19: =IF(F19<>"",J18-I19-K19,"") -> 1484474.1
B20: Total kostnad i % av lånesum | C20: =IFERROR($C$19/$C$3%,"") -> 43.508315 | D20: =IFERROR($D$19/$C$3%,"") | F20: =IF(F19<>"",IF(J19>1,F19+1,""),"") -> 17 | G20: =IF(F20<>"",IF(J19>$C$15,$C$15,J19+H20),"") -> 6099.1034 | H20: =IF(F20<>"",J19*$C$4%/$C$7+$C$8,"") -> 3142.6544 | I20: =IF(F20<>"",IF(F20>$C$6*$C$7,G20-H20,0),"") -> 2956.449 | J20: =IF(F20<>"",J19-I20-K20,"") -> 1481517.7
B21: Termingebyr utgjør | C21: =C8*C7*C5 -> 18000 | F21: =IF(F20<>"",IF(J20>1,F20+1,""),"") -> 18 | G21: =IF(F21<>"",IF(J20>$C$15,$C$15,J20+H21),"") -> 6099.1034 | H21: =IF(F21<>"",J20*$C$4%/$C$7+$C$8,"") -> 3136.4951 | I21: =IF(F21<>"",IF(F21>$C$6*$C$7,G21-H21,0),"") -> 2962.6083 | J21: =IF(F21<>"",J20-I21-K21,"") -> 1478555.1
F22: =IF(F21<>"",IF(J21>1,F21+1,""),"") -> 19 | G22: =IF(F22<>"",IF(J21>$C$15,$C$15,J21+H22),"") -> 6099.1034 | H22: =IF(F22<>"",J21*$C$4%/$C$7+$C$8,"") -> 3130.323 | I22: =IF(F22<>"",IF(F22>$C$6*$C$7,G22-H22,0),"") -> 2968.7804 | J22: =IF(F22<>"",J21-I22-K22,"") -> 1475586.3
B23: Kostnad ved forskjellig nedbetalingstid | D23: % | F23: =IF(F22<>"",IF(J22>1,F22+1,""),"") -> 20 | G23: =IF(F23<>"",IF(J22>$C$15,$C$15,J22+H23),"") -> 6099.1034 | H23: =IF(F23<>"",J22*$C$4%/$C$7+$C$8,"") -> 3124.1381 | I23: =IF(F23<>"",IF(F23>$C$6*$C$7,G23-H23,0),"") -> 2974.9653 | J23: =IF(F23<>"",J22-I23-K23,"") -> 1472611.3
A24: =3-$C$6 -> 3 | B24: =A24+$C$6&" år" -> 3 år | C24: =IFERROR((PMT($C$4%/$C$7,A24*$C$7,$C$14)*-1)*$C$7*A24-$C$14+($C$15*$C$6*$C$7)+$C$8*$C$5*$C$7+$C$18,"") -> 78671.631 | D24: =IFERROR(C24/$C$3%,"") -> 5.1419366 | F24: =IF(F23<>"",IF(J23>1,F23+1,""),"") -> 21 | G24: =IF(F24<>"",IF(J23>$C$15,$C$15,J23+H24),"") -> 6099.1034 | H24: =IF(F24<>"",J23*$C$4%/$C$7+$C$8,"") -> 3117.9402 | I24: =IF(F24<>"",IF(F24>$C$6*$C$7,G24-H24,0),"") -> 2981.1632 | J24: =IF(F24<>"",J23-I24-K24,"") -> 1469630.1
A25: =4-$C$6 -> 4 | B25: =A25+$C$6&" år" -> 4 år | C25: =IFERROR((PMT($C$4%/$C$7,A25*$C$7,$C$14)*-1)*$C$7*A25-$C$14+($C$15*$C$6*$C$7)+$C$8*$C$5*$C$7+$C$18,"") -> 98365.939 | D25: =IFERROR(C25/$C$3%,"") -> 6.4291463 | F25: =IF(F24<>"",IF(J24>1,F24+1,""),"") -> 22 | G25: =IF(F25<>"",IF(J24>$C$15,$C$15,J24+H25),"") -> 6099.1034 | H25: =IF(F25<>"",J24*$C$4%/$C$7+$C$8,"") -> 3111.7295 | I25: =IF(F25<>"",IF(F25>$C$6*$C$7,G25-H25,0),"") -> 2987.3739 | J25: =IF(F25<>"",J24-I25-K25,"") -> 1466642.8
A26: =5-$C$6 -> 5 | B26: =A26+$C$6&" år" -> 5 år | C26: =IFERROR((PMT($C$4%/$C$7,A26*$C$7,$C$14)*-1)*$C$7*A26-$C$14+($C$15*$C$6*$C$7)+$C$8*$C$5*$C$7+$C$18,"") -> 118219.39 | D26: =IFERROR(C26/$C$3%,"") -> 7.7267578 | F26: =IF(F25<>"",IF(J25>1,F25+1,""),"") -> 23 | G26: =IF(F26<>"",IF(J25>$C$15,$C$15,J25+H26),"") -> 6099.1034 | H26: =IF(F26<>"",J25*$C$4%/$C$7+$C$8,"") -> 3105.5058 | I26: =IF(F26<>"",IF(F26>$C$6*$C$7,G26-H26,0),"") -> 2993.5976 | J26: =IF(F26<>"",J25-I26-K26,"") -> 1463649.2
A27: =6-$C$6 -> 6 | B27: =A27+$C$6&" år" -> 6 år | C27: =IFERROR((PMT($C$4%/$C$7,A27*$C$7,$C$14)*-1)*$C$7*A27-$C$14+($C$15*$C$6*$C$7)+$C$8*$C$5*$C$7+$C$18,"") -> 138231.91 | D27: =IFERROR(C27/$C$3%,"") -> 9.0347653 | F27: =IF(F26<>"",IF(J26>1,F26+1,""),"") -> 24 | G27: =IF(F27<>"",IF(J26>$C$15,$C$15,J26+H27),"") -> 6099.1034 | H27: =IF(F27<>"",J26*$C$4%/$C$7+$C$8,"") -> 3099.2691 | I27: =IF(F27<>"",IF(F27>$C$6*$C$7,G27-H27,0),"") -> 2999.8343 | J27: =IF(F27<>"",J26-I27-K27,"") -> 1460649.3
A28: =7-$C$6 -> 7 | B28: =A28+$C$6&" år" -> 7 år | C28: =IFERROR((PMT($C$4%/$C$7,A28*$C$7,$C$14)*-1)*$C$7*A28-$C$14+($C$15*$C$6*$C$7)+$C$8*$C$5*$C$7+$C$18,"") -> 158403.37 | D28: =IFERROR(C28/$C$3%,"") -> 10.353162 | F28: =IF(F27<>"",IF(J27>1,F27+1,""),"") -> 25 | G28: =IF(F28<>"",IF(J27>$C$15,$C$15,J27+H28),"") -> 6099.1034 | H28: =IF(F28<>"",J27*$C$4%/$C$7+$C$8,"") -> 3093.0195 | I28: =IF(F28<>"",IF(F28>$C$6*$C$7,G28-H28,0),"") -> 3006.0839 | J28: =IF(F28<>"",J27-I28-K28,"") -> 1457643.3
A29: =10-$C$6 -> 10 | B29: =A29+$C$6&" år" -> 10 år | C29: =IFERROR((PMT($C$4%/$C$7,A29*$C$7,$C$14)*-1)*$C$7*A29-$C$14+($C$15*$C$6*$C$7)+$C$8*$C$5*$C$7+$C$18,"") -> 219870.07 | D29: =IFERROR(C29/$C$3%,"") -> 14.370593 | F29: =IF(F28<>"",IF(J28>1,F28+1,""),"") -> 26 | G29: =IF(F29<>"",IF(J28>$C$15,$C$15,J28+H29),"") -> 6099.1034 | H29: =IF(F29<>"",J28*$C$4%/$C$7+$C$8,"") -> 3086.7568 | I29: =IF(F29<>"",IF(F29>$C$6*$C$7,G29-H29,0),"") -> 3012.3466 | J29: =IF(F29<>"",J28-I29-K29,"") -> 1454630.9
A30: 15 | B30: =A30+$C$6&" år" -> 15 år | C30: =IFERROR((PMT($C$4%/$C$7,A30*$C$7,$C$14)*-1)*$C$7*A30-$C$14+($C$15*$C$6*$C$7)+$C$8*$C$5*$C$7+$C$18,"") -> 325477.69 | D30: =IFERROR(C30/$C$3%,"") -> 21.273052 | F30: =IF(F29<>"",IF(J29>1,F29+1,""),"") -> 27 | G30: =IF(F30<>"",IF(J29>$C$15,$C$15,J29+H30),"") -> 6099.1034 | H30: =IF(F30<>"",J29*$C$4%/$C$7+$C$8,"") -> 3080.4811 | I30: =IF(F30<>"",IF(F30>$C$6*$C$7,G30-H30,0),"") -> 3018.6223 | J30: =IF(F30<>"",J29-I30-K30,"") -> 1451612.3
A31: =20-$C$6 -> 20 | B31: =A31+$C$6&" år" -> 20 år | C31: =IFERROR((PMT($C$4%/$C$7,A31*$C$7,$C$14)*-1)*$C$7*A31-$C$14+($C$15*$C$6*$C$7)+$C$8*$C$5*$C$7+$C$18,"") -> 435011.6 | D31: =IFERROR(C31/$C$3%,"") -> 28.432131 | F31: =IF(F30<>"",IF(J30>1,F30+1,""),"") -> 28 | G31: =IF(F31<>"",IF(J30>$C$15,$C$15,J30+H31),"") -> 6099.1034 | H31: =IF(F31<>"",J30*$C$4%/$C$7+$C$8,"") -> 3074.1923 | I31: =IF(F31<>"",IF(F31>$C$6*$C$7,G31-H31,0),"") -> 3024.9111 | J31: =IF(F31<>"",J30-I31-K31,"") -> 1448587.4
A32: =25-$C$6 -> 25 | B32: =A32+$C$6&" år" -> 25 år | C32: =IFERROR((PMT($C$4%/$C$7,A32*$C$7,$C$14)*-1)*$C$7*A32-$C$14+($C$15*$C$6*$C$7)+$C$8*$C$5*$C$7+$C$18,"") -> 548429.37 | D32: =IFERROR(C32/$C$3%,"") -> 35.845057 | F32: =IF(F31<>"",IF(J31>1,F31+1,""),"") -> 29 | G32: =IF(F32<>"",IF(J31>$C$15,$C$15,J31+H32),"") -> 6099.1034 | H32: =IF(F32<>"",J31*$C$4%/$C$7+$C$8,"") -> 3067.8904 | I32: =IF(F32<>"",IF(F32>$C$6*$C$7,G32-H32,0),"") -> 3031.213 | J32: =IF(F32<>"",J31-I32-K32,"") -> 1445556.2
A33: =30-$C$6 -> 30 | B33: =A33+$C$6&" år" -> 30 år | C33: =IFERROR((PMT($C$4%/$C$7,A33*$C$7,$C$14)*-1)*$C$7*A33-$C$14+($C$15*$C$6*$C$7)+$C$8*$C$5*$C$7+$C$18,"") -> 665677.22 | D33: =IFERROR(C33/$C$3%,"") -> 43.508315 | F33: =IF(F32<>"",IF(J32>1,F32+1,""),"") -> 30 | G33: =IF(F33<>"",IF(J32>$C$15,$C$15,J32+H33),"") -> 6099.1034 | H33: =IF(F33<>"",J32*$C$4%/$C$7+$C$8,"") -> 3061.5753 | I33: =IF(F33<>"",IF(F33>$C$6*$C$7,G33-H33,0),"") -> 3037.5281 | J33: =IF(F33<>"",J32-I33-K33,"") -> 1442518.6
A34: =35-$C$6 -> 35 | B34: =A34+$C$6&" år" -> 35 år | C34: =IFERROR((PMT($C$4%/$C$7,A34*$C$7,$C$14)*-1)*$C$7*A34-$C$14+($C$15*$C$6*$C$7)+$C$8*$C$5*$C$7+$C$18,"") -> 786690.66 | D34: =IFERROR(C34/$C$3%,"") -> 51.41769 | F34: =IF(F33<>"",IF(J33>1,F33+1,""),"") -> 31 | G34: =IF(F34<>"",IF(J33>$C$15,$C$15,J33+H34),"") -> 6099.1034 | H34: =IF(F34<>"",J33*$C$4%/$C$7+$C$8,"") -> 3055.2471 | I34: =IF(F34<>"",IF(F34>$C$6*$C$7,G34-H34,0),"") -> 3043.8563 | J34: =IF(F34<>"",J33-I34-K34,"") -> 1439474.8
A35: =40-$C$6 -> 40 | B35: =A35+$C$6&" år" -> 40 år | C35: =IFERROR((PMT($C$4%/$C$7,A35*$C$7,$C$14)*-1)*$C$7*A35-$C$14+($C$15*$C$6*$C$7)+$C$8*$C$5*$C$7+$C$18,"") -> 911395.09 | D35: =IFERROR(C35/$C$3%,"") -> 59.568307 | F35: =IF(F34<>"",IF(J34>1,F34+1,""),"") -> 32 | G35: =IF(F35<>"",IF(J34>$C$15,$C$15,J34+H35),"") -> 6099.1034 | H35: =IF(F35<>"",J34*$C$4%/$C$7+$C$8,"") -> 3048.9058 | I35: =IF(F35<>"",IF(F35>$C$6*$C$7,G35-H35,0),"") -> 3050.1976 | J35: =IF(F35<>"",J34-I35-K35,"") -> 1436424.6
F36: =IF(F35<>"",IF(J35>1,F35+1,""),"") -> 33 | G36: =IF(F36<>"",IF(J35>$C$15,$C$15,J35+H36),"") -> 6099.1034 | H36: =IF(F36<>"",J35*$C$4%/$C$7+$C$8,"") -> 3042.5512 | I36: =IF(F36<>"",IF(F36>$C$6*$C$7,G36-H36,0),"") -> 3056.5522 | J36: =IF(F36<>"",J35-I36-K36,"") -> 1433368
B37: Effekt av ekstra innbetaling | F37: =IF(F36<>"",IF(J36>1,F36+1,""),"") -> 34 | G37: =IF(F37<>"",IF(J36>$C$15,$C$15,J36+H37),"") -> 6099.1034 | H37: =IF(F37<>"",J36*$C$4%/$C$7+$C$8,"") -> 3036.1834 | I37: =IF(F37<>"",IF(F37>$C$6*$C$7,G37-H37,0),"") -> 3062.92 | J37: =IF(F37<>"",J36-I37-K37,"") -> 1430305.1
B38: Sum renter | C38: =SUM(H:H) -> 664727.22 | F38: =IF(F37<>"",IF(J37>1,F37+1,""),"") -> 35 | G38: =IF(F38<>"",IF(J37>$C$15,$C$15,J37+H38),"") -> 6099.1034 | H38: =IF(F38<>"",J37*$C$4%/$C$7+$C$8,"") -> 3029.8023 | I38: =IF(F38<>"",IF(F38>$C$6*$C$7,G38-H38,0),"") -> 3069.3011 | J38: =IF(F38<>"",J37-I38-K38,"") -> 1427235.8
B39: Ekstra innbetalt | C39: =SUM(K:K) -> 0 | F39: =IF(F38<>"",IF(J38>1,F38+1,""),"") -> 36 | G39: =IF(F39<>"",IF(J38>$C$15,$C$15,J38+H39),"") -> 6099.1034 | H39: =IF(F39<>"",J38*$C$4%/$C$7+$C$8,"") -> 3023.4079 | I39: =IF(F39<>"",IF(F39>$C$6*$C$7,G39-H39,0),"") -> 3075.6955 | J39: =IF(F39<>"",J38-I39-K39,"") -> 1424160.1
B40: Spart rentekostnad | C40: =C17-C38 -> 0 | F40: =IF(F39<>"",IF(J39>1,F39+1,""),"") -> 37 | G40: =IF(F40<>"",IF(J39>$C$15,$C$15,J39+H40),"") -> 6099.1034 | H40: =IF(F40<>"",J39*$C$4%/$C$7+$C$8,"") -> 3017.0002 | I40: =IF(F40<>"",IF(F40>$C$6*$C$7,G40-H40,0),"") -> 3082.1032 | J40: =IF(F40<>"",J39-I40-K40,"") -> 1421078
F41: =IF(F40<>"",IF(J40>1,F40+1,""),"") -> 38 | G41: =IF(F41<>"",IF(J40>$C$15,$C$15,J40+H41),"") -> 6099.1034 | H41: =IF(F41<>"",J40*$C$4%/$C$7+$C$8,"") -> 3010.5792 | I41: =IF(F41<>"",IF(F41>$C$6*$C$7,G41-H41,0),"") -> 3088.5242 | J41: =IF(F41<>"",J40-I41-K41,"") -> 1417989.5
...

Sheet Lån B
B2: Lånebeløp og betingelser | F2: Termin | G2: Terminbeløp | H2: Renter | I2: Avdrag | J2: Restgjeld | K2: Ekstra innbetalt | L2: Periode | M2: Renter pr. År | N2: Avdrag pr. År
B3: Lån | C3: ='Sammenligning A og B'!G14 -> 2040000 | F3: 0 | J3: =C14 -> 2040950
B4: Nominell rente per år (PA) | C4: ='Sammenligning A og B'!C13 -> 2.5 | F4: =IF(F3<>"",IF(J3>1,F3+1,""),"") -> 1 | G4: =IF(F4<>"",IF(J3>$C$15,$C$15,J3+H4),"") -> 8114.22 | H4: =IF(F4<>"",J3*$C$4%/$C$7+$C$8,"") -> 4301.9792 | I4: =IF(F4<>"",IF(F4>$C$6*$C$7,G4-H4,0),"") -> 3812.2408 | J4: =IF(F4<>"",J3-I4-K4,"") -> 2037137.8 | L4: År 1 | M4: =SUM(H4:H15) -> 51095.91 | N4: =SUM(I4:I15) -> 46274.73
B5: Nedbetalingstid, antall år | C5: 30 | F5: =IF(F4<>"",IF(J4>1,F4+1,""),"") -> 2 | G5: =IF(F5<>"",IF(J4>$C$15,$C$15,J4+H5),"") -> 8114.22 | H5: =IF(F5<>"",J4*$C$4%/$C$7+$C$8,"") -> 4294.037 | I5: =IF(F5<>"",IF(F5>$C$6*$C$7,G5-H5,0),"") -> 3820.183 | J5: =IF(F5<>"",J4-I5-K5,"") -> 2033317.6 | L5: År 2 | M5: =SUM(H16:H27) -> 49925.693 | N5: =SUM(I16:I27) -> 47444.947
B6: Avdragsfrie år | C6: ='Sammenligning A og B'!E9 -> 0 | F6: =IF(F5<>"",IF(J5>1,F5+1,""),"") -> 3 | G6: =IF(F6<>"",IF(J5>$C$15,$C$15,J5+H6),"") -> 8114.22 | H6: =IF(F6<>"",J5*$C$4%/$C$7+$C$8,"") -> 4286.0783 | I6: =IF(F6<>"",IF(F6>$C$6*$C$7,G6-H6,0),"") -> 3828.1417 | J6: =IF(F6<>"",J5-I6-K6,"") -> 2029489.4 | L6: År 3 | M6: =SUM(H28:H39) -> 48725.884 | N6: =SUM(I28:I39) -> 48644.756
B7: Terminer per år | C7: 12 | F7: =IF(F6<>"",IF(J6>1,F6+1,""),"") -> 4 | G7: =IF(F7<>"",IF(J6>$C$15,$C$15,J6+H7),"") -> 8114.22 | H7: =IF(F7<>"",J6*$C$4%/$C$7+$C$8,"") -> 4278.103 | I7: =IF(F7<>"",IF(F7>$C$6*$C$7,G7-H7,0),"") -> 3836.117 | J7: =IF(F7<>"",J6-I7-K7,"") -> 2025653.3 | L7: År 4 | M7: =SUM(H40:H51) -> 47495.733 | N7: =SUM(I40:I51) -> 49874.907
B8: Termingebyr | C8: 50 | F8: =IF(F7<>"",IF(J7>1,F7+1,""),"") -> 5 | G8: =IF(F8<>"",IF(J7>$C$15,$C$15,J7+H8),"") -> 8114.22 | H8: =IF(F8<>"",J7*$C$4%/$C$7+$C$8,"") -> 4270.1111 | I8: =IF(F8<>"",IF(F8>$C$6*$C$7,G8-H8,0),"") -> 3844.1089 | J8: =IF(F8<>"",J7-I8-K8,"") -> 2021809.2 | L8: År 5 | M8: =SUM(H52:H63) -> 46234.473 | N8: =SUM(I52:I63) -> 51136.166
B9: Tinglysningsgebyr | F9: =IF(F8<>"",IF(J8>1,F8+1,""),"") -> 6 | G9: =IF(F9<>"",IF(J8>$C$15,$C$15,J8+H9),"") -> 8114.22 | H9: =IF(F9<>"",J8*$C$4%/$C$7+$C$8,"") -> 4262.1025 | I9: =IF(F9<>"",IF(F9>$C$6*$C$7,G9-H9,0),"") -> 3852.1175 | J9: =IF(F9<>"",J8-I9-K9,"") -> 2017957.1 | L9: År 6 | M9: =SUM(H64:H75) -> 44941.319 | N9: =SUM(I64:I75) -> 52429.321
B10: Etableringsgebyr | C10: 950 | F10: =IF(F9<>"",IF(J9>1,F9+1,""),"") -> 7 | G10: =IF(F10<>"",IF(J9>$C$15,$C$15,J9+H10),"") -> 8114.22 | H10: =IF(F10<>"",J9*$C$4%/$C$7+$C$8,"") -> 4254.0773 | I10: =IF(F10<>"",IF(F10>$C$6*$C$7,G10-H10,0),"") -> 3860.1427 | J10: =IF(F10<>"",J9-I10-K10,"") -> 2014096.9 | L10: År 7 | M10: =SUM(H76:H87) -> 43615.462 | N10: =SUM(I76:I87) -> 53755.178
B11: Inkludere gebyrer i lånebeløp? | C11: Ja | F11: =IF(F10<>"",IF(J10>1,F10+1,""),"") -> 8 | G11: =IF(F11<>"",IF(J10>$C$15,$C$15,J10+H11),"") -> 8114.22 | H11: =IF(F11<>"",J10*$C$4%/$C$7+$C$8,"") -> 4246.0353 | I11: =IF(F11<>"",IF(F11>$C$6*$C$7,G11-H11,0),"") -> 3868.1847 | J11: =IF(F11<>"",J10-I11-K11,"") -> 2010228.8 | L11: År 8 | M11: =SUM(H88:H99) -> 42256.076 | N11: =SUM(I88:I99) -> 55114.563
F12: =IF(F11<>"",IF(J11>1,F11+1,""),"") -> 9 | G12: =IF(F12<>"",IF(J11>$C$15,$C$15,J11+H12),"") -> 8114.22 | H12: =IF(F12<>"",J11*$C$4%/$C$7+$C$8,"") -> 4237.9766 | I12: =IF(F12<>"",IF(F12>$C$6*$C$7,G12-H12,0),"") -> 3876.2434 | J12: =IF(F12<>"",J11-I12-K12,"") -> 2006352.5 | L12: År 9 | M12: =SUM(H100:H111) -> 40862.314 | N12: =SUM(I100:I111) -> 56508.326
B13: Avdrag, renter andre kostnader | D13: Effekt ekstra innb | F13: =IF(F12<>"",IF(J12>1,F12+1,""),"") -> 10 | G13: =IF(F13<>"",IF(J12>$C$15,$C$15,J12+H13),"") -> 8114.22 | H13: =IF(F13<>"",J12*$C$4%/$C$7+$C$8,"") -> 4229.9011 | I13: =IF(F13<>"",IF(F13>$C$6*$C$7,G13-H13,0),"") -> 3884.3189 | J13: =IF(F13<>"",J12-I13-K13,"") -> 2002468.2 | L13: År 10 | M13: =SUM(H112:H123) -> 39433.306 | N13: =SUM(I112:I123) -> 57937.334
B14: Lånebeløp inkl gebyrer | C14: =C3+IF(C11="Ja",C9+C10,0) -> 2040950 | F14: =IF(F13<>"",IF(J13>1,F13+1,""),"") -> 11 | G14: =IF(F14<>"",IF(J13>$C$15,$C$15,J13+H14),"") -> 8114.22 | H14: =IF(F14<>"",J13*$C$4%/$C$7+$C$8,"") -> 4221.8088 | I14: =IF(F14<>"",IF(F14>$C$6*$C$7,G14-H14,0),"") -> 3892.4112 | J14: =IF(F14<>"",J13-I14-K14,"") -> 1998575.8
B15: Avdrag og rente/termin | C15: =IFERROR(PMT(C4%/C7,(C5-C6)*C7,C14)*-1+C8,"") -> 8114.22 | F15: =IF(F14<>"",IF(J14>1,F14+1,""),"") -> 12 | G15: =IF(F15<>"",IF(J14>$C$15,$C$15,J14+H15),"") -> 8114.22 | H15: =IF(F15<>"",J14*$C$4%/$C$7+$C$8,"") -> 4213.6996 | I15: =IF(F15<>"",IF(F15>$C$6*$C$7,G15-H15,0),"") -> 3900.5204 | J15: =IF(F15<>"",J14-I15-K15,"") -> 1994675.3
B16: Nedbetalt i perioden | C16: =IFERROR(C15*C7*(C5-C6)+(C15*C6*C7),"") -> 2921119.2 | D16: =IF(SUM(K:K)<>0, SUM(H:I)-C16,"") | F16: =IF(F15<>"",IF(J15>1,F15+1,""),"") -> 13 | G16: =IF(F16<>"",IF(J15>$C$15,$C$15,J15+H16),"") -> 8114.22 | H16: =IF(F16<>"",J15*$C$4%/$C$7+$C$8,"") -> 4205.5735 | I16: =IF(F16<>"",IF(F16>$C$6*$C$7,G16-H16,0),"") -> 3908.6465 | J16: =IF(F16<>"",J15-I16-K16,"") -> 1990766.6
B17: Renter | C17: =IFERROR(C16-C14,"") -> 880169.19 | D17: =IF(SUM(K:K)<>0, SUM(H:H)-C17,"") | F17: =IF(F16<>"",IF(J16>1,F16+1,""),"") -> 14 | G17: =IF(F17<>"",IF(J16>$C$15,$C$15,J16+H17),"") -> 8114.22 | H17: =IF(F17<>"",J16*$C$4%/$C$7+$C$8,"") -> 4197.4305 | I17: =IF(F17<>"",IF(F17>$C$6*$C$7,G17-H17,0),"") -> 3916.7895 | J17: =IF(F17<>"",J16-I17-K17,"") -> 1986849.8
B18: Etablering og tinglysning | C18: =C9+C10 -> 950 | F18: =IF(F17<>"",IF(J17>1,F17+1,""),"") -> 15 | G18: =IF(F18<>"",IF(J17>$C$15,$C$15,J17+H18),"") -> 8114.22 | H18: =IF(F18<>"",J17*$C$4%/$C$7+$C$8,"") -> 4189.2705 | I18: =IF(F18<>"",IF(F18>$C$6*$C$7,G18-H18,0),"") -> 3924.9495 | J18: =IF(F18<>"",J17-I18-K18,"") -> 1982924.9
B19: Sum kostnader | C19: =SUM(C17:C18) -> 881119.19 | D19: =IFERROR(D17+D18,"") | F19: =IF(F18<>"",IF(J18>1,F18+1,""),"") -> 16 | G19: =IF(F19<>"",IF(J18>$C$15,$C$15,J18+H19),"") -> 8114.22 | H19: =IF(F19<>"",J18*$C$4%/$C$7+$C$8,"") -> 4181.0935 | I19: =IF(F19<>"",IF(F19>$C$6*$C$7,G19-H19,0),"") -> 3933.1265 | J19: =IF(F19<>"",J18-I19-K19,"") -> 1978991.8
B20: Total kostnad i % av lånesum | C20: =IFERROR($C$19/$C$3%,"") -> 43.192117 | D20: =IFERROR($D$19/$C$3%,"") | F20: =IF(F19<>"",IF(J19>1,F19+1,""),"") -> 17 | G20: =IF(F20<>"",IF(J19>$C$15,$C$15,J19+H20),"") -> 8114.22 | H20: =IF(F20<>"",J19*$C$4%/$C$7+$C$8,"") -> 4172.8995 | I20: =IF(F20<>"",IF(F20>$C$6*$C$7,G20-H20,0),"") -> 3941.3205 | J20: =IF(F20<>"",J19-I20-K20,"") -> 1975050.4
B21: Termingebyr utgjør | C21: =C8*C7*C5 -> 18000 | F21: =IF(F20<>"",IF(J20>1,F20+1,""),"") -> 18 | G21: =IF(F21<>"",IF(J20>$C$15,$C$15,J20+H21),"") -> 8114.22 | H21: =IF(F21<>"",J20*$C$4%/$C$7+$C$8,"") -> 4164.6884 | I21: =IF(F21<>"",IF(F21>$C$6*$C$7,G21-H21,0),"") -> 3949.5316 | J21: =IF(F21<>"",J20-I21-K21,"") -> 1971100.9
F22: =IF(F21<>"",IF(J21>1,F21+1,""),"") -> 19 | G22: =IF(F22<>"",IF(J21>$C$15,$C$15,J21+H22),"") -> 8114.22 | H22: =IF(F22<>"",J21*$C$4%/$C$7+$C$8,"") -> 4156.4602 | I22: =IF(F22<>"",IF(F22>$C$6*$C$7,G22-H22,0),"") -> 3957.7598 | J22: =IF(F22<>"",J21-I22-K22,"") -> 1967143.1
B23: Kostnad ved forskjellig nedbetalingstid | D23: % | F23: =IF(F22<>"",IF(J22>1,F22+1,""),"") -> 20 | G23: =IF(F23<>"",IF(J22>$C$15,$C$15,J22+H23),"") -> 8114.22 | H23: =IF(F23<>"",J22*$C$4%/$C$7+$C$8,"") -> 4148.2149 | I23: =IF(F23<>"",IF(F23>$C$6*$C$7,G23-H23,0),"") -> 3966.0051 | J23: =IF(F23<>"",J22-I23-K23,"") -> 1963177.1
A24: =3-$C$6 -> 3 | B24: =A24+$C$6&" år" -> 3 år | C24: =IFERROR((PMT($C$4%/$C$7,A24*$C$7,$C$14)*-1)*$C$7*A24-$C$14+($C$15*$C$6*$C$7)+$C$8*$C$5*$C$7+$C$18,"") -> 98566.488 | D24: =IFERROR(C24/$C$3%,"") -> 4.8316906 | F24: =IF(F23<>"",IF(J23>1,F23+1,""),"") -> 21 | G24: =IF(F24<>"",IF(J23>$C$15,$C$15,J23+H24),"") -> 8114.22 | H24: =IF(F24<>"",J23*$C$4%/$C$7+$C$8,"") -> 4139.9524 | I24: =IF(F24<>"",IF(F24>$C$6*$C$7,G24-H24,0),"") -> 3974.2676 | J24: =IF(F24<>"",J23-I24-K24,"") -> 1959202.9
A25: =4-$C$6 -> 4 | B25: =A25+$C$6&" år" -> 4 år | C25: =IFERROR((PMT($C$4%/$C$7,A25*$C$7,$C$14)*-1)*$C$7*A25-$C$14+($C$15*$C$6*$C$7)+$C$8*$C$5*$C$7+$C$18,"") -> 124821.49 | D25: =IFERROR(C25/$C$3%,"") -> 6.1187006 | F25: =IF(F24<>"",IF(J24>1,F24+1,""),"") -> 22 | G25: =IF(F25<>"",IF(J24>$C$15,$C$15,J24+H25),"") -> 8114.22 | H25: =IF(F25<>"",J24*$C$4%/$C$7+$C$8,"") -> 4131.6727 | I25: =IF(F25<>"",IF(F25>$C$6*$C$7,G25-H25,0),"") -> 3982.5473 | J25: =IF(F25<>"",J24-I25-K25,"") -> 1955220.3
A26: =5-$C$6 -> 5 | B26: =A26+$C$6&" år" -> 5 år | C26: =IFERROR((PMT($C$4%/$C$7,A26*$C$7,$C$14)*-1)*$C$7*A26-$C$14+($C$15*$C$6*$C$7)+$C$8*$C$5*$C$7+$C$18,"") -> 151288.66 | D26: =IFERROR(C26/$C$3%,"") -> 7.4161108 | F26: =IF(F25<>"",IF(J25>1,F25+1,""),"") -> 23 | G26: =IF(F26<>"",IF(J25>$C$15,$C$15,J25+H26),"") -> 8114.22 | H26: =IF(F26<>"",J25*$C$4%/$C$7+$C$8,"") -> 4123.3757 | I26: =IF(F26<>"",IF(F26>$C$6*$C$7,G26-H26,0),"") -> 3990.8443 | J26: =IF(F26<>"",J25-I26-K26,"") -> 1951229.5
A27: =6-$C$6 -> 6 | B27: =A27+$C$6&" år" -> 6 år | C27: =IFERROR((PMT($C$4%/$C$7,A27*$C$7,$C$14)*-1)*$C$7*A27-$C$14+($C$15*$C$6*$C$7)+$C$8*$C$5*$C$7+$C$18,"") -> 177967.87 | D27: =IFERROR(C27/$C$3%,"") -> 8.7239153 | F27: =IF(F26<>"",IF(J26>1,F26+1,""),"") -> 24 | G27: =IF(F27<>"",IF(J26>$C$15,$C$15,J26+H27),"") -> 8114.22 | H27: =IF(F27<>"",J26*$C$4%/$C$7+$C$8,"") -> 4115.0614 | I27: =IF(F27<>"",IF(F27>$C$6*$C$7,G27-H27,0),"") -> 3999.1586 | J27: =IF(F27<>"",J26-I27-K27,"") -> 1947230.3
A28: =7-$C$6 -> 7 | B28: =A28+$C$6&" år" -> 7 år | C28: =IFERROR((PMT($C$4%/$C$7,A28*$C$7,$C$14)*-1)*$C$7*A28-$C$14+($C$15*$C$6*$C$7)+$C$8*$C$5*$C$7+$C$18,"") -> 204858.99 | D28: =IFERROR(C28/$C$3%,"") -> 10.042107 | F28: =IF(F27<>"",IF(J27>1,F27+1,""),"") -> 25 | G28: =IF(F28<>"",IF(J27>$C$15,$C$15,J27+H28),"") -> 8114.22 | H28: =IF(F28<>"",J27*$C$4%/$C$7+$C$8,"") -> 4106.7298 | I28: =IF(F28<>"",IF(F28>$C$6*$C$7,G28-H28,0),"") -> 4007.4901 | J28: =IF(F28<>"",J27-I28-K28,"") -> 1943222.8
A29: =10-$C$6 -> 10 | B29: =A29+$C$6&" år" -> 10 år | C29: =IFERROR((PMT($C$4%/$C$7,A29*$C$7,$C$14)*-1)*$C$7*A29-$C$14+($C$15*$C$6*$C$7)+$C$8*$C$5*$C$7+$C$18,"") -> 286801.87 | D29: =IFERROR(C29/$C$3%,"") -> 14.058915 | F29: =IF(F28<>"",IF(J28>1,F28+1,""),"") -> 26 | G29: =IF(F29<>"",IF(J28>$C$15,$C$15,J28+H29),"") -> 8114.22 | H29: =IF(F29<>"",J28*$C$4%/$C$7+$C$8,"") -> 4098.3809 | I29: =IF(F29<>"",IF(F29>$C$6*$C$7,G29-H29,0),"") -> 4015.8391 | J29: =IF(F29<>"",J28-I29-K29,"") -> 1939207
A30: 15 | B30: =A30+$C$6&" år" -> 15 år | C30: =IFERROR((PMT($C$4%/$C$7,A30*$C$7,$C$14)*-1)*$C$7*A30-$C$14+($C$15*$C$6*$C$7)+$C$8*$C$5*$C$7+$C$18,"") -> 427590.19 | D30: =IFERROR(C30/$C$3%,"") -> 20.960303 | F30: =IF(F29<>"",IF(J29>1,F29+1,""),"") -> 27 | G30: =IF(F30<>"",IF(J29>$C$15,$C$15,J29+H30),"") -> 8114.22 | H30: =IF(F30<>"",J29*$C$4%/$C$7+$C$8,"") -> 4090.0146 | I30: =IF(F30<>"",IF(F30>$C$6*$C$7,G30-H30,0),"") -> 4024.2054 | J30: =IF(F30<>"",J29-I30-K30,"") -> 1935182.8
A31: =20-$C$6 -> 20 | B31: =A31+$C$6&" år" -> 20 år | C31: =IFERROR((PMT($C$4%/$C$7,A31*$C$7,$C$14)*-1)*$C$7*A31-$C$14+($C$15*$C$6*$C$7)+$C$8*$C$5*$C$7+$C$18,"") -> 573612.74 | D31: =IFERROR(C31/$C$3%,"") -> 28.118272 | F31: =IF(F30<>"",IF(J30>1,F30+1,""),"") -> 28 | G31: =IF(F31<>"",IF(J30>$C$15,$C$15,J30+H31),"") -> 8114.22 | H31: =IF(F31<>"",J30*$C$4%/$C$7+$C$8,"") -> 4081.6308 | I31: =IF(F31<>"",IF(F31>$C$6*$C$7,G31-H31,0),"") -> 4032.5892 | J31: =IF(F31<>"",J30-I31-K31,"") -> 1931150.2
A32: =25-$C$6 -> 25 | B32: =A32+$C$6&" år" -> 25 år | C32: =IFERROR((PMT($C$4%/$C$7,A32*$C$7,$C$14)*-1)*$C$7*A32-$C$14+($C$15*$C$6*$C$7)+$C$8*$C$5*$C$7+$C$18,"") -> 724812.97 | D32: =IFERROR(C32/$C$3%,"") -> 35.530048 | F32: =IF(F31<>"",IF(J31>1,F31+1,""),"") -> 29 | G32: =IF(F32<>"",IF(J31>$C$15,$C$15,J31+H32),"") -> 8114.22 | H32: =IF(F32<>"",J31*$C$4%/$C$7+$C$8,"") -> 4073.2296 | I32: =IF(F32<>"",IF(F32>$C$6*$C$7,G32-H32,0),"") -> 4040.9904 | J32: =IF(F32<>"",J31-I32-K32,"") -> 1927109.2
A33: =30-$C$6 -> 30 | B33: =A33+$C$6&" år" -> 30 år | C33: =IFERROR((PMT($C$4%/$C$7,A33*$C$7,$C$14)*-1)*$C$7*A33-$C$14+($C$15*$C$6*$C$7)+$C$8*$C$5*$C$7+$C$18,"") -> 881119.19 | D33: =IFERROR(C33/$C$3%,"") -> 43.192117 | F33: =IF(F32<>"",IF(J32>1,F32+1,""),"") -> 30 | G33: =IF(F33<>"",IF(J32>$C$15,$C$15,J32+H33),"") -> 8114.22 | H33: =IF(F33<>"",J32*$C$4%/$C$7+$C$8,"") -> 4064.8109 | I33: =IF(F33<>"",IF(F33>$C$6*$C$7,G33-H33,0),"") -> 4049.4091 | J33: =IF(F33<>"",J32-I33-K33,"") -> 1923059.8
A34: =35-$C$6 -> 35 | B34: =A34+$C$6&" år" -> 35 år | C34: =IFERROR((PMT($C$4%/$C$7,A34*$C$7,$C$14)*-1)*$C$7*A34-$C$14+($C$15*$C$6*$C$7)+$C$8*$C$5*$C$7+$C$18,"") -> 1042445.4 | D34: =IFERROR(C34/$C$3%,"") -> 51.100265 | F34: =IF(F33<>"",IF(J33>1,F33+1,""),"") -> 31 | G34: =IF(F34<>"",IF(J33>$C$15,$C$15,J33+H34),"") -> 8114.22 | H34: =IF(F34<>"",J33*$C$4%/$C$7+$C$8,"") -> 4056.3746 | I34: =IF(F34<>"",IF(F34>$C$6*$C$7,G34-H34,0),"") -> 4057.8454 | J34: =IF(F34<>"",J33-I34-K34,"") -> 1919002
A35: =40-$C$6 -> 40 | B35: =A35+$C$6&" år" -> 40 år | C35: =IFERROR((PMT($C$4%/$C$7,A35*$C$7,$C$14)*-1)*$C$7*A35-$C$14+($C$15*$C$6*$C$7)+$C$8*$C$5*$C$7+$C$18,"") -> 1208692.2 | D35: =IFERROR(C35/$C$3%,"") -> 59.249617 | F35: =IF(F34<>"",IF(J34>1,F34+1,""),"") -> 32 | G35: =IF(F35<>"",IF(J34>$C$15,$C$15,J34+H35),"") -> 8114.22 | H35: =IF(F35<>"",J34*$C$4%/$C$7+$C$8,"") -> 4047.9207 | I35: =IF(F35<>"",IF(F35>$C$6*$C$7,G35-H35,0),"") -> 4066.2992 | J35: =IF(F35<>"",J34-I35-K35,"") -> 1914935.7
F36: =IF(F35<>"",IF(J35>1,F35+1,""),"") -> 33 | G36: =IF(F36<>"",IF(J35>$C$15,$C$15,J35+H36),"") -> 8114.22 | H36: =IF(F36<>"",J35*$C$4%/$C$7+$C$8,"") -> 4039.4493 | I36: =IF(F36<>"",IF(F36>$C$6*$C$7,G36-H36,0),"") -> 4074.7707 | J36: =IF(F36<>"",J35-I36-K36,"") -> 1910860.9
B37: Effekt av ekstra innbetaling | F37: =IF(F36<>"",IF(J36>1,F36+1,""),"") -> 34 | G37: =IF(F37<>"",IF(J36>$C$15,$C$15,J36+H37),"") -> 8114.22 | H37: =IF(F37<>"",J36*$C$4%/$C$7+$C$8,"") -> 4030.9602 | I37: =IF(F37<>"",IF(F37>$C$6*$C$7,G37-H37,0),"") -> 4083.2598 | J37: =IF(F37<>"",J36-I37-K37,"") -> 1906777.6
B38: Sum renter | C38: =SUM(H:H) -> 880169.19 | F38: =IF(F37<>"",IF(J37>1,F37+1,""),"") -> 35 | G38: =IF(F38<>"",IF(J37>$C$15,$C$15,J37+H38),"") -> 8114.22 | H38: =IF(F38<>"",J37*$C$4%/$C$7+$C$8,"") -> 4022.4534 | I38: =IF(F38<>"",IF(F38>$C$6*$C$7,G38-H38,0),"") -> 4091.7666 | J38: =IF(F38<>"",J37-I38-K38,"") -> 1902685.9
B39: Ekstra innbetalt | C39: =SUM(K:K) -> 0 | F39: =IF(F38<>"",IF(J38>1,F38+1,""),"") -> 36 | G39: =IF(F39<>"",IF(J38>$C$15,$C$15,J38+H39),"") -> 8114.22 | H39: =IF(F39<>"",J38*$C$4%/$C$7+$C$8,"") -> 4013.9289 | I39: =IF(F39<>"",IF(F39>$C$6*$C$7,G39-H39,0),"") -> 4100.2911 | J39: =IF(F39<>"",J38-I39-K39,"") -> 1898585.6
B40: Spart rentekostnad | C40: =C17-C38 -> -1.7462298e-09 | F40: =IF(F39<>"",IF(J39>1,F39+1,""),"") -> 37 | G40: =IF(F40<>"",IF(J39>$C$15,$C$15,J39+H40),"") -> 8114.22 | H40: =IF(F40<>"",J39*$C$4%/$C$7+$C$8,"") -> 4005.3866 | I40: =IF(F40<>"",IF(F40>$C$6*$C$7,G40-H40,0),"") -> 4108.8334 | J40: =IF(F40<>"",J39-I40-K40,"") -> 1894476.7
F41: =IF(F40<>"",IF(J40>1,F40+1,""),"") -> 38 | G41: =IF(F41<>"",IF(J40>$C$15,$C$15,J40+H41),"") -> 8114.22 | H41: =IF(F41<>"",J40*$C$4%/$C$7+$C$8,"") -> 3996.8265 | I41: =IF(F41<>"",IF(F41>$C$6*$C$7,G41-H41,0),"") -> 4117.3935 | J41: =IF(F41<>"",J40-I41-K41,"") -> 1890359.3
...

Sheet Bruksanvisning
B2: Bruksanvisning
B4: Det er ganske enkelt oppsett i arkene:
C6: Celler i denne fargen skal ikke røres
C8: Celler i denne fargen fyller du ut dine tall i
C10: De mørkegrå inneholder formler og der får du ut ferdig behandlede tall.
C11: De lysegrå legger du inn ønsket kjøpesum, renter, leieinntekter, kostnader etc.
C13: De ulike lånekalkulatorene er koblet til aktuelle ark og skal ikke røres.
C14: Alt i lånekalkulatorene hentes fra det arket det er koblet sammen.
C15: Hvis du skal dra ut kalkylearket og lage et eget Excel ark må du huske på å ta med
C16: fanen som er merket Lån - Kalkyle 2021 f. eks.
C18: Kalkyle - 2021 er for å regne på eiendom og kunne legge ved som vedlegg til bank
C19: ved søk om finansiering på nye objekter.
C21: Oversikt 1 objekt er det jeg har brukt til hver eiendom, så det kopierer jeg bare og lager ett ekstra
